Workbook
Name Slicer_Class: #N/A
Name Slicer_Class1: #N/A
Name Slicer_Class2: #N/A

Sheet Dataset
A1: Student Name | B1: Class | C1: Section | D1: Roll Number | E1: Phone Number | F1: Gender | G1: Age | H1: Fee Status | I1: Entry Pass Collected | J1: Food Preference | K1: Academic Event Participation | L1: Cultural Event Participation
A2: Parth Bansal | B2: 9 | C2: A | D2: 11 | E2: 6544792178 | F2: Male | G2: 14 | H2: Paid | I2: No | J2: Non-Veg | K2: Quiz | L2: Singing
A3: Kunal Mukherjee | B3: 10 | C3: D | D3: 110 | E3: 6460754249 | F3: Male | G3: 15 | H3: Paid | I3: Yes | J3: Veg | K3: Science Fair | L3: Singing
A4: Nikita Malhotra | B4: 8 | C4: C | D4: 7 | E4: 7310555924 | F4: Female | G4: 13 | H4: Paid | I4: Yes | J4: Veg | K4: Quiz | L4: None
A5: Jyoti Tiwari | B5: 6 | C5: A | D5: 87 | E5: 9472488976 | F5: Female | G5: 12 | H5: Paid | I5: No | J5: Veg | K5: Drawing | L5: Dance
A6: Madhuri Ghosh | B6: 8 | C6: D | D6: 163 | E6: 6030232886 | F6: Female | G6: 13 | H6: Due | I6: Yes | J6: Non-Veg | K6: None | L6: None
A7: Riya Joshi | B7: 10 | C7: D | D7: 40 | E7: 9545949157 | F7: Female | G7: 15 | H7: Paid | I7: Yes | J7: Veg | K7: Science Fair | L7: None
A8: Veer Malhotra | B8: 9 | C8: C | D8: 69 | E8: 7171797340 | F8: Male | G8: 15 | H8: Due | I8: No | J8: Veg | K8: None | L8: Singing
A9: Amrita Mondal | B9: 7 | C9: B | D9: 149 | E9: 8149672906 | F9: Female | G9: 12 | H9: Paid | I9: No | J9: Veg | K9: Science Fair | L9: Dance
A10: Shikha Bajaj | B10: 6 | C10: B | D10: 193 | E10: 9188660590 | F10: Female | G10: 11 | H10: Due | I10: No | J10: Veg | K10: Drawing | L10: None
A11: Vanya Kapoor | B11: 10 | C11: D | D11: 178 | E11: 9965307298 | F11: Female | G11: 15 | H11: Paid | I11: Yes | J11: Non-Veg | K11: Quiz | L11: Singing
A12: Ishan Arora | B12: 9 | C12: B | D12: 96 | E12: 6352855056 | F12: Male | G12: 14 | H12: Paid | I12: Yes | J12: Veg | K12: None | L12: None
A13: Vishal Bansal | B13: 9 | C13: B | D13: 68 | E13: 7093300591 | F13: Male | G13: 15 | H13: Due | I13: Yes | J13: Veg | K13: Science Fair | L13: Drama
... A601: Madhav Verma | B601: 9 | C601: C | D601: 95 | E601: 8479317163 | F601: Male | G601: 15 | H601: Paid | I601: No | J601: Non-Veg | K601: None | L601: Drama

Sheet Questions
B1: QUESTIONS
B2: 1 | C2: Identify whether each student has paid the fee or not. | K2: Class | L2: Fee
B3: 2 | C3: Categorize students into Junior and Senior groups based on class. | K3: 6 | L3: 50
B4: 3 | C4: Count the total number of students whose fee status is "Due". | K4: 7 | L4: 60
B5: 4 | C5: Food Preference of Students | K5: 8 | L5: 70
B6: 5 | C6: Entry Pass Collected By Students | K6: 9 | L6: 80
B7: 6 | C7: Count how many students are in each Class who paid fees | K7: 10 | L7: 90
B8: 7 | C8: Calculate the total fees collected from students.
B9: 8 | C9: Calculate the total pending fees.
B10: 9 | C10: Find the total fees collected from any Class students.
B11: 10 | C11: Find the expected fee for each student using a lookup table.
B12: 11 | C12: Check whether the fee remark paid by each student.
B13: 12 | C13: Apply conditional formatting to highlight:
C14: Students with "Due" fees
C15: Students with "Paid" fees
B16: 13 | C16: Create a dropdown list for cultural event participation.
B17: 14 | C17: Calculate class-wise total collected fees.
B18: 15 | C18: Count the number of students participating in Cultural event.
B19: 16 | C19: Count the number of students participating in Academic event.
B20: 17 | C20: Create a dashboard showing:
C21: Total Students
C22: Total Paid Students
C23: Total Due Students
C24: Total Revenue
B25: 18 | C25: Prepare a summary showing class-wise number of Paid and Due students.

Sheet Answers
A1: SCHOOL PROGRAM ANALYSIS
A2: Student Name | B2: Class | C2: Section | D2: Roll Number | E2: Gender | F2: Age | G2: Fee Status | H2: Entry Pass Collected | I2: Food Preference | J2: Academic Event Participation | K2: Cultural Event Participation | L2: Group | M2: Fee Remark | N2: Expected Fee | P2: Q3. Count total students whose fee is Due | S2: =COUNTIF(Dataset!$H$2:$H$601,"Due") -> 261
A3: Garima Rajput | B3: 6 | C3: A | D3: 7 | E3: Female | F3: 12 | G3: Due | H3: Yes | I3: Non-Veg | J3: Drawing | K3: None | L3: =IF(B3<=7,"Junior","Senior") -> Junior | M3: =IF(G3="Paid","OK","Pending") -> Pending | N3: =VLOOKUP(B3,Questions!$K$2:$L$7,2,FALSE) -> 50 | W3: Dashboard
A4: Navya Reddy | B4: 6 | C4: A | D4: 14 | E4: Female | F4: 11 | G4: Due | H4: No | I4: Non-Veg | J4: None | K4: Drama | L4: =IF(B4<=7,"Junior","Senior") -> Junior | M4: =IF(G4="Paid","OK","Pending") -> Pending | N4: =VLOOKUP(B4,Questions!$K$2:$L$7,2,FALSE) -> 50 | P4: Q4. Food Preference of Students | W4: Total Students | X4: =COUNTA(A3:A602) -> 600
A5: Poonam Bhatia | B5: 6 | C5: A | D5: 25 | E5: Female | F5: 12 | G5: Paid | H5: No | I5: Non-Veg | J5: None | K5: None | L5: =IF(B5<=7,"Junior","Senior") -> Junior | M5: =IF(G5="Paid","OK","Pending") -> OK | N5: =VLOOKUP(B5,Questions!$K$2:$L$7,2,FALSE) -> 50 | Q5: Non-Veg | R5: =(COUNTIF(Answers!I3:I602,Q5)/COUNTA(Answers!I3:I602)) -> 0.47833333 | W5: Total Paid | X5: =COUNTIF(G3:G602,"Paid") -> 339
A6: Palak Chauhan | B6: 6 | C6: A | D6: 29 | E6: Female | F6: 11 | G6: Due | H6: No | I6: Veg | J6: None | K6: Singing | L6: =IF(B6<=7,"Junior","Senior") -> Junior | M6: =IF(G6="Paid","OK","Pending") -> Pending | N6: =VLOOKUP(B6,Questions!$K$2:$L$7,2,FALSE) -> 50 | W6: Total Due | X6: =COUNTIF(G3:G602,"Due") -> 261
A7: Alok Tiwari | B7: 6 | C7: A | D7: 31 | E7: Male | F7: 12 | G7: Due | H7: No | I7: Non-Veg | J7: None | K7: Singing | L7: =IF(B7<=7,"Junior","Senior") -> Junior | M7: =IF(G7="Paid","OK","Pending") -> Pending | N7: =VLOOKUP(B7,Questions!$K$2:$L$7,2,FALSE) -> 50 | P7: Q5. Entry Pass Collected By Students | S7: No | T7: =COUNTIF($H$3:$H$602,S7) -> 292 | W7: Total Revenue | X7: =SUMIF(G3:G602,"Paid",N3:N602) -> 23630
A8: Tushar Chopra | B8: 6 | C8: A | D8: 32 | E8: Male | F8: 12 | G8: Paid | H8: No | I8: Veg | J8: Quiz | K8: None | L8: =IF(B8<=7,"Junior","Senior") -> Junior | M8: =IF(G8="Paid","OK","Pending") -> OK | N8: =VLOOKUP(B8,Questions!$K$2:$L$7,2,FALSE) -> 50 | Z8: Academic Event Participation
A9: Lakshay Mehta | B9: 6 | C9: A | D9: 43 | E9: Male | F9: 12 | G9: Due | H9: Yes | I9: Non-Veg | J9: Drawing | K9: Drama | L9: =IF(B9<=7,"Junior","Senior") -> Junior | M9: =IF(G9="Paid","OK","Pending") -> Pending | N9: =VLOOKUP(B9,Questions!$K$2:$L$7,2,FALSE) -> 50 | P9: Q6. Count how many students are in each Class who paid fees | W9: Event | X9: Count | Z9: Event | AA9: Count
A10: Gaurav Sharma | B10: 6 | C10: A | D10: 50 | E10: Male | F10: 12 | G10: Due | H10: Yes | I10: Non-Veg | J10: None | K10: Drama | L10: =IF(B10<=7,"Junior","Senior") -> Junior | M10: =IF(G10="Paid","OK","Pending") -> Pending | N10: =VLOOKUP(B10,Questions!$K$2:$L$7,2,FALSE) -> 50 | Q10: Class | R10: Total Student | S10: Paid Students | W10: Dance | X10: =COUNTIF($K$3:$K$602,W10) -> 126 | Z10: Drawing | AA10: =COUNTIF($J$3:$J$602,Z10) -> 101
A11: Priyanshi Chopra | B11: 6 | C11: A | D11: 56 | E11: Female | F11: 11 | G11: Paid | H11: Yes | I11: Non-Veg | J11: Quiz | K11: Singing | L11: =IF(B11<=7,"Junior","Senior") -> Junior | M11: =IF(G11="Paid","OK","Pending") -> OK | N11: =VLOOKUP(B11,Questions!$K$2:$L$7,2,FALSE) -> 50 | Q11: 10 | R11: =COUNTIF(Answers!$B$3:$B$602,Q11) -> 126 | S11: =COUNTIFS(Answers!B3:B602,Q11,Answers!G3:G602,"Paid") -> 68 | W11: Drama | X11: =COUNTIF($K$3:$K$602,W11) -> 108 | Z11: None | AA11: =COUNTIF($J$3:$J$602,Z11) -> 219
A12: Rohit Roy | B12: 6 | C12: A | D12: 58 | E12: Male | F12: 11 | G12: Paid | H12: No | I12: Non-Veg | J12: Quiz | K12: Dance | L12: =IF(B12<=7,"Junior","Senior") -> Junior | M12: =IF(G12="Paid","OK","Pending") -> OK | N12: =VLOOKUP(B12,Questions!$K$2:$L$7,2,FALSE) -> 50 | W12: Singing | X12: =COUNTIF($K$3:$K$602,W12) -> 133 | Z12: Quiz | AA12: =COUNTIF($J$3:$J$602,Z12) -> 96
A13: Oviya Tiwari | B13: 6 | C13: A | D13: 59 | E13: Female | F13: 12 | G13: Paid | H13: Yes | I13: Veg | J13: Quiz | K13: Drama | L13: =IF(B13<=7,"Junior","Senior") -> Junior | M13: =IF(G13="Paid","OK","Pending") -> OK | N13: =VLOOKUP(B13,Questions!$K$2:$L$7,2,FALSE) -> 50 | P13: Q7. Calculate total fees collected | S13: =SUMIF(Answers!G2:G602,"Paid",Answers!N2:N602) -> 23630 | W13: None | X13: =COUNTIF($K$3:$K$602,W13) -> 233 | Z13: Science Fair | AA13: =COUNTIF($J$3:$J$602,Z13) -> 106
A14: Yash Dubey | B14: 6 | C14: A | D14: 64 | E14: Male | F14: 11 | G14: Due | H14: Yes | I14: Non-Veg | J14: Quiz | K14: Dance | L14: =IF(B14<=7,"Junior","Senior") -> Junior | M14: =IF(G14="Paid","OK","Pending") -> Pending | N14: =VLOOKUP(B14,Questions!$K$2:$L$7,2,FALSE) -> 50 | P14: Q8. Calculate total pending fees | S14: =SUMIF(Answers!G2:G602,"Due",Answers!N2:N602) -> 18530 | Z14: Olympiad | AA14: =COUNTIF($J$3:$J$602,Z14) -> 78
A15: Khushi Rao | B15: 6 | C15: A | D15: 69 | E15: Female | F15: 12 | G15: Due | H15: Yes | I15: Veg | J15: Science Fair | K15: Singing | L15: =IF(B15<=7,"Junior","Senior") -> Junior | M15: =IF(G15="Paid","OK","Pending") -> Pending | N15: =VLOOKUP(B15,Questions!$K$2:$L$7,2,FALSE) -> 50
A16: Anushka Singh | B16: 6 | C16: A | D16: 71 | E16: Female | F16: 12 | G16: Paid | H16: No | I16: Veg | J16: None | K16: Singing | L16: =IF(B16<=7,"Junior","Senior") -> Junior | M16: =IF(G16="Paid","OK","Pending") -> OK | N16: =VLOOKUP(B16,Questions!$K$2:$L$7,2,FALSE) -> 50 | P16: Q9. Total fees collected from any Class
A17: Neha Reddy | B17: 6 | C17: A | D17: 75 | E17: Female | F17: 11 | G17: Due | H17: Yes | I17: Veg | J17: Science Fair | K17: Dance | L17: =IF(B17<=7,"Junior","Senior") -> Junior | M17: =IF(G17="Paid","OK","Pending") -> Pending | N17: =VLOOKUP(B17,Questions!$K$2:$L$7,2,FALSE) -> 50 | Q17: Class | R17: Total Fees Collect | U17: 14 | V17: Calculate class-wise total collected fees.
A18: Akash Das | B18: 6 | C18: A | D18: 81 | E18: Male | F18: 12 | G18: Due | H18: No | I18: Veg | J18: None | K18: None | L18: =IF(B18<=7,"Junior","Senior") -> Junior | M18: =IF(G18="Paid","OK","Pending") -> Pending | N18: =VLOOKUP(B18,Questions!$K$2:$L$7,2,FALSE) -> 50 | Q18: 7 | R18: =SUMIF(Answers!B3:B602,Answers!Q18,Answers!N3:N602) -> 8280 | V18: Class | W18: Paid | X18: Due: | Y18: Revenue
A19: Jyoti Tiwari | B19: 6 | C19: A | D19: 87 | E19: Female | F19: 12 | G19: Paid | H19: No | I19: Veg | J19: Drawing | K19: Dance | L19: =IF(B19<=7,"Junior","Senior") -> Junior | M19: =IF(G19="Paid","OK","Pending") -> OK | N19: =VLOOKUP(B19,Questions!$K$2:$L$7,2,FALSE) -> 50 | P19: Q15. Count the number of students participating in Cultural event. | V19: 6 | W19: =COUNTIFS($B$3:$B$602,V19,$G$3:$G$602,"Paid") -> 58 | X19: =COUNTIFS($B$3:$B$602,V19,$G$3:$G$602,"Due") -> 48 | Y19: =W19*Questions!L3 -> 2900
A20: Shikha Shukla | B20: 6 | C20: A | D20: 89 | E20: Female | F20: 12 | G20: Paid | H20: Yes | I20: Non-Veg | J20: Science Fair | K20: None | L20: =IF(B20<=7,"Junior","Senior") -> Junior | M20: =IF(G20="Paid","OK","Pending") -> OK | N20: =VLOOKUP(B20,Questions!$K$2:$L$7,2,FALSE) -> 50 | Q20: None | R20: =COUNTIF(Answers!K3:K602,Answers!Q20) -> 233 | V20: 7 | W20: =COUNTIFS($B$3:$B$602,V20,$G$3:$G$602,"Paid") -> 89 | X20: =COUNTIFS($B$3:$B$602,V20,$G$3:$G$602,"Due") -> 49 | Y20: =W20*Questions!L4 -> 5340
A21: Sakshi Srivastava | B21: 6 | C21: A | D21: 95 | E21: Female | F21: 12 | G21: Paid | H21: Yes | I21: Veg | J21: Quiz | K21: Dance | L21: =IF(B21<=7,"Junior","Senior") -> Junior | M21: =IF(G21="Paid","OK","Pending") -> OK | N21: =VLOOKUP(B21,Questions!$K$2:$L$7,2,FALSE) -> 50 | P21: Q16. Count the number of students participating in Academic event. | V21: 8 | W21: =COUNTIFS($B$3:$B$602,V21,$G$3:$G$602,"Paid") -> 65 | X21: =COUNTIFS($B$3:$B$602,V21,$G$3:$G$602,"Due") -> 51 | Y21: =W21*Questions!L5 -> 4550
A22: Akash Roy | B22: 6 | C22: A | D22: 107 | E22: Male | F22: 12 | G22: Paid | H22: Yes | I22: Veg | J22: Olympiad | K22: Singing | L22: =IF(B22<=7,"Junior","Senior") -> Junior | M22: =IF(G22="Paid","OK","Pending") -> OK | N22: =VLOOKUP(B22,Questions!$K$2:$L$7,2,FALSE) -> 50 | Q22: None | R22: =COUNTIF(Answers!J3:J602,Answers!Q22) -> 219 | V22: 9 | W22: =COUNTIFS($B$3:$B$602,V22,$G$3:$G$602,"Paid") -> 59 | X22: =COUNTIFS($B$3:$B$602,V22,$G$3:$G$602,"Due") -> 55 | Y22: =W22*Questions!L6 -> 4720
A23: Dhruv Jain | B23: 6 | C23: A | D23: 126 | E23: Male | F23: 11 | G23: Due | H23: No | I23: Non-Veg | J23: None | K23: Singing | L23: =IF(B23<=7,"Junior","Senior") -> Junior | M23: =IF(G23="Paid","OK","Pending") -> Pending | N23: =VLOOKUP(B23,Questions!$K$2:$L$7,2,FALSE) -> 50 | V23: 10 | W23: =COUNTIFS($B$3:$B$602,V23,$G$3:$G$602,"Paid") -> 68 | X23: =COUNTIFS($B$3:$B$602,V23,$G$3:$G$602,"Due") -> 58 | Y23: =W23*Questions!L7 -> 6120
A24: Vishal Rajput | B24: 6 | C24: A | D24: 128 | E24: Male | F24: 11 | G24: Due | H24: Yes | I24: Veg | J24: Olympiad | K24: None | L24: =IF(B24<=7,"Junior","Senior") -> Junior | M24: =IF(G24="Paid","OK","Pending") -> Pending | N24: =VLOOKUP(B24,Questions!$K$2:$L$7,2,FALSE) -> 50
A25: Arnav Mehta | B25: 6 | C25: A | D25: 132 | E25: Male | F25: 12 | G25: Due | H25: No | I25: Veg | J25: None | K25: Singing | L25: =IF(B25<=7,"Junior","Senior") -> Junior | M25: =IF(G25="Paid","OK","Pending") -> Pending | N25: =VLOOKUP(B25,Questions!$K$2:$L$7,2,FALSE) -> 50 | P25: Q17. Dashboard calculations
A26: Archana Malhotra | B26: 6 | C26: A | D26: 144 | E26: Female | F26: 12 | G26: Paid | H26: No | I26: Non-Veg | J26: Olympiad | K26: None | L26: =IF(B26<=7,"Junior","Senior") -> Junior | M26: =IF(G26="Paid","OK","Pending") -> OK | N26: =VLOOKUP(B26,Questions!$K$2:$L$7,2,FALSE) -> 50 | Q26: Total Students: | S26: =COUNTA(Answers!A3:A602) -> 600
A27: Bhavesh Tiwari | B27: 6 | C27: A | D27: 154 | E27: Male | F27: 11 | G27: Due | H27: Yes | I27: Non-Veg | J27: Drawing | K27: Drama | L27: =IF(B27<=7,"Junior","Senior") -> Junior | M27: =IF(G27="Paid","OK","Pending") -> Pending | N27: =VLOOKUP(B27,Questions!$K$2:$L$7,2,FALSE) -> 50 | Q27: Total Paid Students: | S27: =COUNTIF(Answers!G2:G602,"Paid") -> 339
A28: Arjun Sethi | B28: 6 | C28: A | D28: 158 | E28: Male | F28: 11 | G28: Paid | H28: Yes | I28: Non-Veg | J28: None | K28: Dance | L28: =IF(B28<=7,"Junior","Senior") -> Junior | M28: =IF(G28="Paid","OK","Pending") -> OK | N28: =VLOOKUP(B28,Questions!$K$2:$L$7,2,FALSE) -> 50 | Q28: Total Due: | S28: =COUNTIF(Answers!G2:G602,"Due") -> 261
A29: Gaurav Rao | B29: 6 | C29: A | D29: 175 | E29: Male | F29: 11 | G29: Paid | H29: No | I29: Veg | J29: None | K29: Drama | L29: =IF(B29<=7,"Junior","Senior") -> Junior | M29: =IF(G29="Paid","OK","Pending") -> OK | N29: =VLOOKUP(B29,Questions!$K$2:$L$7,2,FALSE) -> 50 | Q29: Total Revenue: | S29: =SUMIF(Answers!G3:G602,"Paid",Answers!N3:N602) -> 23630
A30: Garima Choudhary | B30: 6 | C30: A | D30: 181 | E30: Female | F30: 12 | G30: Paid | H30: Yes | I30: Non-Veg | J30: Olympiad | K30: None | L30: =IF(B30<=7,"Junior","Senior") -> Junior | M30: =IF(G30="Paid","OK","Pending") -> OK | N30: =VLOOKUP(B30,Questions!$K$2:$L$7,2,FALSE) -> 50
A31: Tarun Iyer | B31: 6 | C31: B | D31: 8 | E31: Male | F31: 12 | G31: Paid | H31: Yes | I31: Veg | J31: Quiz | K31: Drama | L31: =IF(B31<=7,"Junior","Senior") -> Junior | M31: =IF(G31="Paid","OK","Pending") -> OK | N31: =VLOOKUP(B31,Questions!$K$2:$L$7,2,FALSE) -> 50 | P31: Q18. Class-wise Paid vs Due summary
A32: Ansh Tiwari | B32: 6 | C32: B | D32: 11 | E32: Male | F32: 11 | G32: Due | H32: Yes | I32: Non-Veg | J32: Drawing | K32: Dance | L32: =IF(B32<=7,"Junior","Senior") -> Junior | M32: =IF(G32="Paid","OK","Pending") -> Pending | N32: =VLOOKUP(B32,Questions!$K$2:$L$7,2,FALSE) -> 50 | Q32: Class | R32: Paid | S32: Due:
A33: Chhavi Chopra | B33: 6 | C33: B | D33: 19 | E33: Female | F33: 12 | G33: Paid | H33: No | I33: Veg | J33: Drawing | K33: Singing | L33: =IF(B33<=7,"Junior","Senior") -> Junior | M33: =IF(G33="Paid","OK","Pending") -> OK | N33: =VLOOKUP(B33,Questions!$K$2:$L$7,2,FALSE) -> 50 | Q33: 10 | R33: =COUNTIFS(Answers!B3:B602,Q33,Answers!G3:G602,"Paid") -> 68 | S33: =COUNTIFS(Answers!B3:B602,Q33,Answers!G3:G602,"Due") -> 58
A34: Ritika Joshi | B34: 6 | C34: B | D34: 24 | E34: Female | F34: 11 | G34: Paid | H34: No | I34: Non-Veg | J34: Olympiad | K34: None | L34: =IF(B34<=7,"Junior","Senior") -> Junior | M34: =IF(G34="Paid","OK","Pending") -> OK | N34: =VLOOKUP(B34,Questions!$K$2:$L$7,2,FALSE) -> 50
A35: Lokesh Pandey | B35: 6 | C35: B | D35: 33 | E35: Male | F35: 12 | G35: Due | H35: No | I35: Veg | J35: Quiz | K35: Dance | L35: =IF(B35<=7,"Junior","Senior") -> Junior | M35: =IF(G35="Paid","OK","Pending") -> Pending | N35: =VLOOKUP(B35,Questions!$K$2:$L$7,2,FALSE) -> 50
A36: Ansh Joshi | B36: 6 | C36: B | D36: 55 | E36: Male | F36: 11 | G36: Due | H36: Yes | I36: Veg | J36: Drawing | K36: None | L36: =IF(B36<=7,"Junior","Senior") -> Junior | M36: =IF(G36="Paid","OK","Pending") -> Pending | N36: =VLOOKUP(B36,Questions!$K$2:$L$7,2,FALSE) -> 50
A37: Trisha Mehta | B37: 6 | C37: B | D37: 63 | E37: Female | F37: 12 | G37: Due | H37: No | I37: Non-Veg | J37: Science Fair | K37: Drama | L37: =IF(B37<=7,"Junior","Senior") -> Junior | M37: =IF(G37="Paid","OK","Pending") -> Pending | N37: =VLOOKUP(B37,Questions!$K$2:$L$7,2,FALSE) -> 50
A38: Himanshu Naidu | B38: 6 | C38: B | D38: 65 | E38: Male | F38: 12 | G38: Due | H38: Yes | I38: Veg | J38: Drawing | K38: None | L38: =IF(B38<=7,"Junior","Senior") -> Junior | M38: =IF(G38="Paid","OK","Pending") -> Pending | N38: =VLOOKUP(B38,Questions!$K$2:$L$7,2,FALSE) -> 50
A39: Zara Bansal | B39: 6 | C39: B | D39: 76 | E39: Female | F39: 12 | G39: Paid | H39: Yes | I39: Non-Veg | J39: Olympiad | K39: Dance | L39: =IF(B39<=7,"Junior","Senior") -> Junior | M39: =IF(G39="Paid","OK","Pending") -> OK | N39: =VLOOKUP(B39,Questions!$K$2:$L$7,2,FALSE) -> 50
A40: Sanya Srivastava | B40: 6 | C40: B | D40: 85 | E40: Female | F40: 12 | G40: Due | H40: No | I40: Veg | J40: None | K40: Singing | L40: =IF(B40<=7,"Junior","Senior") -> Junior | M40: =IF(G40="Paid","OK","Pending") -> Pending | N40: =VLOOKUP(B40,Questions!$K$2:$L$7,2,FALSE) -> 50
...

Sheet Dashboard
A1: Class | B1: (All) | C1: ="Cultural Event Participation OF CLASS :"&B1 -> Cultural Event Participation OF CLASS :(All)
A3: Row Labels | B3: Sum of Class
A4: Dance | B4: 0.20930233 | C4: =1-B4 -> 0.79069767
A5: Drama | B5: 0.18147841 | C5: =1-B5 -> 0.81852159
A6: None | B6: 0.38683555 | C6: =1-B6 -> 0.61316445
A7: Singing | B7: 0.22238372 | C7: =1-B7 -> 0.77761628
A8: Grand Total | B8: 1
A19: Class | B19: (All) | C19: =" Academic Event Participation OF CLASS :"&B19 -> Academic Event Participation OF CLASS :(All)
A21: Row Labels | B21: Sum of Class
A22: Drawing | B22: 0.16341362 | C22: =1-B22 -> 0.83658638
A23: None | B23: 0.36254153 | C23: =1-B23 -> 0.63745847
A24: Olympiad | B24: 0.13226744 | C24: =1-B24 -> 0.86773256
A25: Quiz | B25: 0.15863787 | C25: =1-B25 -> 0.84136213
A26: Science Fair | B26: 0.18313953 | C26: =1-B26 -> 0.81686047
A27: Grand Total | B27: 1
A31: Class | B31: 9
A33: Sum of Due: | B33: Sum of Paid
A34: 55 | B34: 59
