Workbook

Sheet Sheet1
A1: Order ID | B1: Customer ID | C1: Order Date | D1: Ship Date | E1: City | F1: State | G1: Sales Channel | H1: Payment Method | I1: Product Category | J1: Product Name | K1: Brand | L1: Units Sold | M1: Unit Price | N1: Total Price | O1: Discount % | P1: Discount amount | Q1: Price after discount | R1: Price Category | S1: Unit Category | T1: Discount Category
A2: 10001 | B2: 1102 | C2: 45197 | D2: 45203 | E2: Chennai | F2: Delhi | G2: Mobile App | H2: Credit Card | I2: Home & Kitchen | J2: Mixer Grinder | K2: BrandA | L2: 7 | M2: 2843.87 | N2: =L2*M2 -> 19907.09 | O2: 0 | P2: =N2*O2/100 -> 0 | Q2: =N2-P2 -> 19907.09 | R2: =IF(Q2>=10000,"High","Low") -> High | S2: {=_xlfn.IFS(L2>=8,"High",L2>=5,"Medium",L2<5,"Low")} -> Medium | T2: =IF(P2>=3000,"High",IF(P2>=1500,"Medium","Low")) -> Low | V2: Brand Name | W2: Units Sold | Y2: Average Units Sold
A3: 10002 | B3: 1435 | C3: 45199 | D3: 45203 | E3: Pune | F3: Tamil Nadu | G3: Website | H3: Debit Card | I3: Sports | J3: Football | K3: BrandD | L3: 9 | M3: 2525.23 | N3: =L3*M3 -> 22727.07 | O3: 5 | P3: =N3*O3/100 -> 1136.3535 | Q3: =N3-P3 -> 21590.716 | R3: =IF(Q3>=10000,"High","Low") -> High | S3: {=_xlfn.IFS(L3>=8,"High",L3>=5,"Medium",L3<5,"Low")} -> High | T3: =IF(P3>=3000,"High",IF(P3>=1500,"Medium","Low")) -> Low | V3: BrandB | W3: =SUMIF(K2:K373,V3,L2:L373) -> 354 | Y3: =AVERAGE(L2:L373) -> 4.938172
A4: 10003 | B4: 1860 | C4: 45109 | D4: 45114 | E4: Chennai | F4: West Bengal | G4: Marketplace | H4: Debit Card | I4: Fashion | J4: Sneakers | K4: BrandE | L4: 6 | M4: 3474.34 | N4: =L4*M4 -> 20846.04 | O4: 15 | P4: =N4*O4/100 -> 3126.906 | Q4: =N4-P4 -> 17719.134 | R4: =IF(Q4>=10000,"High","Low") -> High | S4: {=_xlfn.IFS(L4>=8,"High",L4>=5,"Medium",L4<5,"Low")} -> Medium | T4: =IF(P4>=3000,"High",IF(P4>=1500,"Medium","Low")) -> High
A5: 10004 | B5: 1270 | C5: 45079 | D5: 45087 | E5: Bengaluru | F5: West Bengal | G5: Website | H5: Cash on Delivery | I5: Sports | J5: Yoga Mat | K5: BrandA | L5: 1 | M5: 1008.79 | N5: =L5*M5 -> 1008.79 | O5: 15 | P5: =N5*O5/100 -> 151.3185 | Q5: =N5-P5 -> 857.4715 | R5: =IF(Q5>=10000,"High","Low") -> Low | S5: {=_xlfn.IFS(L5>=8,"High",L5>=5,"Medium",L5<5,"Low")} -> Low | T5: =IF(P5>=3000,"High",IF(P5>=1500,"Medium","Low")) -> Low
A6: 10005 | B6: 1106 | C6: 45241 | D6: 45244 | E6: Kolkata | F6: Karnataka | G6: Marketplace | H6: Credit Card | I6: Fashion | J6: Jacket | K6: BrandA | L6: 7 | M6: 3511.47 | N6: =L6*M6 -> 24580.29 | O6: 20 | P6: =N6*O6/100 -> 4916.058 | Q6: =N6-P6 -> 19664.232 | R6: =IF(Q6>=10000,"High","Low") -> High | S6: {=_xlfn.IFS(L6>=8,"High",L6>=5,"Medium",L6<5,"Low")} -> Medium | T6: =IF(P6>=3000,"High",IF(P6>=1500,"Medium","Low")) -> High | V6: Product Category | W6: Brand Name | X6: Units Sold
A7: 10006 | B7: 1071 | C7: 45260 | D7: 45263 | E7: Hyderabad | F7: Telangana | G7: Website | H7: Net Banking | I7: Home & Kitchen | J7: Bedsheet | K7: BrandE | L7: 3 | M7: 3189.55 | N7: =L7*M7 -> 9568.65 | O7: 10 | P7: =N7*O7/100 -> 956.865 | Q7: =N7-P7 -> 8611.785 | R7: =IF(Q7>=10000,"High","Low") -> Low | S7: {=_xlfn.IFS(L7>=8,"High",L7>=5,"Medium",L7<5,"Low")} -> Low | T7: =IF(P7>=3000,"High",IF(P7>=1500,"Medium","Low")) -> Low | V7: Beauty | W7: BrandE | X7: =SUMIFS(L2:L373,I2:I373,V7,K2:K373,W7) -> 89
A8: 10007 | B8: 1700 | C8: 45050 | D8: 45054 | E8: Bengaluru | F8: Telangana | G8: Mobile App | H8: UPI | I8: Fashion | J8: Sneakers | K8: BrandC | L8: 5 | M8: 3030.42 | N8: =L8*M8 -> 15152.1 | O8: 10 | P8: =N8*O8/100 -> 1515.21 | Q8: =N8-P8 -> 13636.89 | R8: =IF(Q8>=10000,"High","Low") -> High | S8: {=_xlfn.IFS(L8>=8,"High",L8>=5,"Medium",L8<5,"Low")} -> Medium | T8: =IF(P8>=3000,"High",IF(P8>=1500,"Medium","Low")) -> Medium
A9: 10008 | B9: 1020 | C9: 45040 | D9: 45041 | E9: Mumbai | F9: Delhi | G9: Website | H9: Credit Card | I9: Fashion | J9: Sneakers | K9: BrandB | L9: 4 | M9: 2310.83 | N9: =L9*M9 -> 9243.32 | O9: 10 | P9: =N9*O9/100 -> 924.332 | Q9: =N9-P9 -> 8318.988 | R9: =IF(Q9>=10000,"High","Low") -> Low | S9: {=_xlfn.IFS(L9>=8,"High",L9>=5,"Medium",L9<5,"Low")} -> Low | T9: =IF(P9>=3000,"High",IF(P9>=1500,"Medium","Low")) -> Low
A10: 10009 | B10: 1614 | C10: 45204 | D10: 45213 | E10: Chennai | F10: West Bengal | G10: Website | H10: Debit Card | I10: Fashion | J10: T-Shirt | K10: BrandD | L10: 5 | M10: 1098.04 | N10: =L10*M10 -> 5490.2 | O10: 15 | P10: =N10*O10/100 -> 823.53 | Q10: =N10-P10 -> 4666.67 | R10: =IF(Q10>=10000,"High","Low") -> Low | S10: {=_xlfn.IFS(L10>=8,"High",L10>=5,"Medium",L10<5,"Low")} -> Medium | T10: =IF(P10>=3000,"High",IF(P10>=1500,"Medium","Low")) -> Low | V10: Brand Name | W10: Average Units Sold
A11: 10010 | B11: 1121 | C11: 45139 | D11: 45147 | E11: Bengaluru | F11: Karnataka | G11: Website | H11: Cash on Delivery | I11: Electronics | J11: Headphones | K11: BrandB | L11: 5 | M11: 1780.66 | N11: =L11*M11 -> 8903.3 | O11: 20 | P11: =N11*O11/100 -> 1780.66 | Q11: =N11-P11 -> 7122.64 | R11: =IF(Q11>=10000,"High","Low") -> Low | S11: {=_xlfn.IFS(L11>=8,"High",L11>=5,"Medium",L11<5,"Low")} -> Medium | T11: =IF(P11>=3000,"High",IF(P11>=1500,"Medium","Low")) -> Medium | V11: BrandB | W11: =AVERAGEIF(K2:K373,V11,L2:L373) -> 4.7837838 | X11: =AVERAGEIF(K2:K373,V11,L2:L373) -> 4.7837838
A12: 10011 | B12: 1466 | C12: 45098 | D12: 45106 | E12: Bengaluru | F12: Karnataka | G12: Mobile App | H12: Cash on Delivery | I12: Electronics | J12: Headphones | K12: BrandE | L12: 6 | M12: 3205.25 | N12: =L12*M12 -> 19231.5 | O12: 0 | P12: =N12*O12/100 -> 0 | Q12: =N12-P12 -> 19231.5 | R12: =IF(Q12>=10000,"High","Low") -> High | S12: {=_xlfn.IFS(L12>=8,"High",L12>=5,"Medium",L12<5,"Low")} -> Medium | T12: =IF(P12>=3000,"High",IF(P12>=1500,"Medium","Low")) -> Low
A13: 10012 | B13: 1214 | C13: 45214 | D13: 45220 | E13: Mumbai | F13: Tamil Nadu | G13: Website | H13: UPI | I13: Electronics | J13: Smartwatch | K13: BrandA | L13: 6 | M13: 272.35 | N13: =L13*M13 -> 1634.1 | O13: 5 | P13: =N13*O13/100 -> 81.705 | Q13: =N13-P13 -> 1552.395 | R13: =IF(Q13>=10000,"High","Low") -> Low | S13: {=_xlfn.IFS(L13>=8,"High",L13>=5,"Medium",L13<5,"Low")} -> Medium | T13: =IF(P13>=3000,"High",IF(P13>=1500,"Medium","Low")) -> Low | V13: Product Category | W13: Brand Name | X13: Average Units Sold
A14: 10013 | B14: 1330 | C14: 45100 | D14: 45107 | E14: Delhi | F14: Tamil Nadu | G14: Mobile App | H14: Cash on Delivery | I14: Home & Kitchen | J14: Bedsheet | K14: BrandA | L14: 8 | M14: 3160.9 | N14: =L14*M14 -> 25287.2 | O14: 0 | P14: =N14*O14/100 -> 0 | Q14: =N14-P14 -> 25287.2 | R14: =IF(Q14>=10000,"High","Low") -> High | S14: {=_xlfn.IFS(L14>=8,"High",L14>=5,"Medium",L14<5,"Low")} -> High | T14: =IF(P14>=3000,"High",IF(P14>=1500,"Medium","Low")) -> Low | V14: Beauty | W14: BrandE | X14: =AVERAGEIFS(L2:L373,I2:I373,V14,K2:K373,W14) -> 5.2352941 | Y14: =AVERAGEIFS(L2:L373,I2:I373,V14,K2:K373,W14) -> 5.2352941
A15: 10014 | B15: 1458 | C15: 45039 | D15: 45045 | E15: Kolkata | F15: Karnataka | G15: Marketplace | H15: Cash on Delivery | I15: Sports | J15: Yoga Mat | K15: BrandD | L15: 8 | M15: 1074.27 | N15: =L15*M15 -> 8594.16 | O15: 15 | P15: =N15*O15/100 -> 1289.124 | Q15: =N15-P15 -> 7305.036 | R15: =IF(Q15>=10000,"High","Low") -> Low | S15: {=_xlfn.IFS(L15>=8,"High",L15>=5,"Medium",L15<5,"Low")} -> High | T15: =IF(P15>=3000,"High",IF(P15>=1500,"Medium","Low")) -> Low
A16: 10015 | B16: 1087 | C16: 45048 | D16: 45057 | E16: Hyderabad | F16: Tamil Nadu | G16: Website | H16: Credit Card | I16: Beauty | J16: Shampoo | K16: BrandA | L16: 9 | M16: 705.59 | N16: =L16*M16 -> 6350.31 | O16: 10 | P16: =N16*O16/100 -> 635.031 | Q16: =N16-P16 -> 5715.279 | R16: =IF(Q16>=10000,"High","Low") -> Low | S16: {=_xlfn.IFS(L16>=8,"High",L16>=5,"Medium",L16<5,"Low")} -> High | T16: =IF(P16>=3000,"High",IF(P16>=1500,"Medium","Low")) -> Low
A17: 10016 | B17: 1372 | C17: 44958 | D17: 44961 | E17: Pune | F17: West Bengal | G17: Mobile App | H17: Net Banking | I17: Fashion | J17: Jacket | K17: BrandA | L17: 8 | M17: 595.45 | N17: =L17*M17 -> 4763.6 | O17: 5 | P17: =N17*O17/100 -> 238.18 | Q17: =N17-P17 -> 4525.42 | R17: =IF(Q17>=10000,"High","Low") -> Low | S17: {=_xlfn.IFS(L17>=8,"High",L17>=5,"Medium",L17<5,"Low")} -> High | T17: =IF(P17>=3000,"High",IF(P17>=1500,"Medium","Low")) -> Low | V17: Tandra
A18: 10017 | B18: 1099 | C18: 45148 | D18: 45151 | E18: Delhi | F18: Maharashtra | G18: Mobile App | H18: UPI | I18: Fashion | J18: Jacket | K18: BrandD | L18: 2 | M18: 254.91 | N18: =L18*M18 -> 509.82 | O18: 15 | P18: =N18*O18/100 -> 76.473 | Q18: =N18-P18 -> 433.347 | R18: =IF(Q18>=10000,"High","Low") -> Low | S18: {=_xlfn.IFS(L18>=8,"High",L18>=5,"Medium",L18<5,"Low")} -> Low | T18: =IF(P18>=3000,"High",IF(P18>=1500,"Medium","Low")) -> Low | V18: 45 | W18: =AVERAGEA(V17:V21) -> 17.2
A19: 10018 | B19: 1871 | C19: 45045 | D19: 45048 | E19: Chennai | F19: West Bengal | G19: Website | H19: Credit Card | I19: Home & Kitchen | J19: Curtains | K19: BrandD | L19: 1 | M19: 2165.81 | N19: =L19*M19 -> 2165.81 | O19: 15 | P19: =N19*O19/100 -> 324.8715 | Q19: =N19-P19 -> 1840.9385 | R19: =IF(Q19>=10000,"High","Low") -> Low | S19: {=_xlfn.IFS(L19>=8,"High",L19>=5,"Medium",L19<5,"Low")} -> Low | T19: =IF(P19>=3000,"High",IF(P19>=1500,"Medium","Low")) -> Low | V19: 40
A20: 10019 | B20: 1663 | C20: 44965 | D20: 44968 | E20: Bengaluru | F20: Karnataka | G20: Marketplace | H20: Net Banking | I20: Fashion | J20: Jacket | K20: BrandE | L20: 2 | M20: 990.3 | N20: =L20*M20 -> 1980.6 | O20: 15 | P20: =N20*O20/100 -> 297.09 | Q20: =N20-P20 -> 1683.51 | R20: =IF(Q20>=10000,"High","Low") -> Low | S20: {=_xlfn.IFS(L20>=8,"High",L20>=5,"Medium",L20<5,"Low")} -> Low | T20: =IF(P20>=3000,"High",IF(P20>=1500,"Medium","Low")) -> Low | V20: TRUE
A21: 10020 | B21: 1130 | C21: 45194 | D21: 45203 | E21: Mumbai | F21: Karnataka | G21: Mobile App | H21: Credit Card | I21: Electronics | J21: Smartwatch | K21: BrandA | L21: 2 | M21: 3959.31 | N21: =L21*M21 -> 7918.62 | O21: 5 | P21: =N21*O21/100 -> 395.931 | Q21: =N21-P21 -> 7522.689 | R21: =IF(Q21>=10000,"High","Low") -> Low | S21: {=_xlfn.IFS(L21>=8,"High",L21>=5,"Medium",L21<5,"Low")} -> Low | T21: =IF(P21>=3000,"High",IF(P21>=1500,"Medium","Low")) -> Low | V21: FALSE
A22: 10021 | B22: 1661 | C22: 45159 | D22: 45163 | E22: Mumbai | F22: West Bengal | G22: Website | H22: Credit Card | I22: Beauty | J22: Lipstick | K22: BrandA | L22: 3 | M22: 2361.58 | N22: =L22*M22 -> 7084.74 | O22: 5 | P22: =N22*O22/100 -> 354.237 | Q22: =N22-P22 -> 6730.503 | R22: =IF(Q22>=10000,"High","Low") -> Low | S22: {=_xlfn.IFS(L22>=8,"High",L22>=5,"Medium",L22<5,"Low")} -> Low | T22: =IF(P22>=3000,"High",IF(P22>=1500,"Medium","Low")) -> Low
A23: 10022 | B23: 1308 | C23: 44944 | D23: 44951 | E23: Kolkata | F23: Tamil Nadu | G23: Marketplace | H23: Cash on Delivery | I23: Books | J23: Fiction Novel | K23: BrandE | L23: 7 | M23: 680.86 | N23: =L23*M23 -> 4766.02 | O23: 20 | P23: =N23*O23/100 -> 953.204 | Q23: =N23-P23 -> 3812.816 | R23: =IF(Q23>=10000,"High","Low") -> Low | S23: {=_xlfn.IFS(L23>=8,"High",L23>=5,"Medium",L23<5,"Low")} -> Medium | T23: =IF(P23>=3000,"High",IF(P23>=1500,"Medium","Low")) -> Low | V23: Total selling amount | W23: =SUM(N2:N373) -> 3664518.5
A24: 10023 | B24: 1769 | C24: 45075 | D24: 45084 | E24: Delhi | F24: Tamil Nadu | G24: Mobile App | H24: Net Banking | I24: Fashion | J24: Sneakers | K24: BrandC | L24: 2 | M24: 2801.74 | N24: =L24*M24 -> 5603.48 | O24: 20 | P24: =N24*O24/100 -> 1120.696 | Q24: =N24-P24 -> 4482.784 | R24: =IF(Q24>=10000,"High","Low") -> Low | S24: {=_xlfn.IFS(L24>=8,"High",L24>=5,"Medium",L24<5,"Low")} -> Low | T24: =IF(P24>=3000,"High",IF(P24>=1500,"Medium","Low")) -> Low
A25: 10024 | B25: 1343 | C25: 45075 | D25: 45082 | E25: Pune | F25: Telangana | G25: Mobile App | H25: UPI | I25: Electronics | J25: Smartwatch | K25: BrandC | L25: 1 | M25: 3606.31 | N25: =L25*M25 -> 3606.31 | O25: 0 | P25: =N25*O25/100 -> 0 | Q25: =N25-P25 -> 3606.31 | R25: =IF(Q25>=10000,"High","Low") -> Low | S25: {=_xlfn.IFS(L25>=8,"High",L25>=5,"Medium",L25<5,"Low")} -> Low | T25: =IF(P25>=3000,"High",IF(P25>=1500,"Medium","Low")) -> Low | V25: Total selling amount | W25: =SUMPRODUCT(L2:L373,M2:M373) -> 3664518.5
A26: 10025 | B26: 1491 | C26: 45052 | D26: 45061 | E26: Kolkata | F26: Karnataka | G26: Marketplace | H26: UPI | I26: Books | J26: Comics | K26: BrandC | L26: 6 | M26: 3018.94 | N26: =L26*M26 -> 18113.64 | O26: 5 | P26: =N26*O26/100 -> 905.682 | Q26: =N26-P26 -> 17207.958 | R26: =IF(Q26>=10000,"High","Low") -> High | S26: {=_xlfn.IFS(L26>=8,"High",L26>=5,"Medium",L26<5,"Low")} -> Medium | T26: =IF(P26>=3000,"High",IF(P26>=1500,"Medium","Low")) -> Low
A27: 10026 | B27: 1413 | C27: 45228 | D27: 45231 | E27: Bengaluru | F27: Delhi | G27: Marketplace | H27: Net Banking | I27: Beauty | J27: Perfume | K27: BrandE | L27: 9 | M27: 444.29 | N27: =L27*M27 -> 3998.61 | O27: 5 | P27: =N27*O27/100 -> 199.9305 | Q27: =N27-P27 -> 3798.6795 | R27: =IF(Q27>=10000,"High","Low") -> Low | S27: {=_xlfn.IFS(L27>=8,"High",L27>=5,"Medium",L27<5,"Low")} -> High | T27: =IF(P27>=3000,"High",IF(P27>=1500,"Medium","Low")) -> Low
A28: 10027 | B28: 1805 | C28: 45286 | D28: 45290 | E28: Kolkata | F28: Telangana | G28: Website | H28: Cash on Delivery | I28: Books | J28: Fiction Novel | K28: BrandA | L28: 3 | M28: 3599.15 | N28: =L28*M28 -> 10797.45 | O28: 5 | P28: =N28*O28/100 -> 539.8725 | Q28: =N28-P28 -> 10257.578 | R28: =IF(Q28>=10000,"High","Low") -> High | S28: {=_xlfn.IFS(L28>=8,"High",L28>=5,"Medium",L28<5,"Low")} -> Low | T28: =IF(P28>=3000,"High",IF(P28>=1500,"Medium","Low")) -> Low | V28: Total selling amount | W28: BrandA | X28: {=SUMPRODUCT(L2:L373,M2:M373,--(K2:K373=W28))} -> 737855.54
A29: 10028 | B29: 1385 | C29: 45164 | D29: 45172 | E29: Hyderabad | F29: Tamil Nadu | G29: Website | H29: Debit Card | I29: Electronics | J29: Smartwatch | K29: BrandE | L29: 6 | M29: 3206.63 | N29: =L29*M29 -> 19239.78 | O29: 20 | P29: =N29*O29/100 -> 3847.956 | Q29: =N29-P29 -> 15391.824 | R29: =IF(Q29>=10000,"High","Low") -> High | S29: {=_xlfn.IFS(L29>=8,"High",L29>=5,"Medium",L29<5,"Low")} -> Medium | T29: =IF(P29>=3000,"High",IF(P29>=1500,"Medium","Low")) -> High
A30: 10029 | B30: 1191 | C30: 45061 | D30: 45067 | E30: Mumbai | F30: West Bengal | G30: Mobile App | H30: Credit Card | I30: Sports | J30: Football | K30: BrandE | L30: 3 | M30: 759.47 | N30: =L30*M30 -> 2278.41 | O30: 15 | P30: =N30*O30/100 -> 341.7615 | Q30: =N30-P30 -> 1936.6485 | R30: =IF(Q30>=10000,"High","Low") -> Low | S30: {=_xlfn.IFS(L30>=8,"High",L30>=5,"Medium",L30<5,"Low")} -> Low | T30: =IF(P30>=3000,"High",IF(P30>=1500,"Medium","Low")) -> Low
A31: 10030 | B31: 1955 | C31: 45077 | D31: 45082 | E31: Mumbai | F31: Tamil Nadu | G31: Marketplace | H31: Cash on Delivery | I31: Sports | J31: Cricket Bat | K31: BrandC | L31: 1 | M31: 349.38 | N31: =L31*M31 -> 349.38 | O31: 10 | P31: =N31*O31/100 -> 34.938 | Q31: =N31-P31 -> 314.442 | R31: =IF(Q31>=10000,"High","Low") -> Low | S31: {=_xlfn.IFS(L31>=8,"High",L31>=5,"Medium",L31<5,"Low")} -> Low | T31: =IF(P31>=3000,"High",IF(P31>=1500,"Medium","Low")) -> Low | V31: Product Name | W31: Brand | X31: Units Sold | Y31: Unit Price
A32: 10031 | B32: 1276 | C32: 45162 | D32: 45166 | E32: Chennai | F32: West Bengal | G32: Marketplace | H32: Net Banking | I32: Books | J32: Textbook | K32: BrandB | L32: 5 | M32: 2295.65 | N32: =L32*M32 -> 11478.25 | O32: 20 | P32: =N32*O32/100 -> 2295.65 | Q32: =N32-P32 -> 9182.6 | R32: =IF(Q32>=10000,"High","Low") -> Low | S32: {=_xlfn.IFS(L32>=8,"High",L32>=5,"Medium",L32<5,"Low")} -> Medium | T32: =IF(P32>=3000,"High",IF(P32>=1500,"Medium","Low")) -> Medium | V32: Mixer Grinder | W32: BrandA | X32: 7 | Y32: 2843.87
A33: 10032 | B33: 1160 | C33: 45150 | D33: 45158 | E33: Chennai | F33: Telangana | G33: Marketplace | H33: Credit Card | I33: Home & Kitchen | J33: Bedsheet | K33: BrandA | L33: 4 | M33: 750.74 | N33: =L33*M33 -> 3002.96 | O33: 5 | P33: =N33*O33/100 -> 150.148 | Q33: =N33-P33 -> 2852.812 | R33: =IF(Q33>=10000,"High","Low") -> Low | S33: {=_xlfn.IFS(L33>=8,"High",L33>=5,"Medium",L33<5,"Low")} -> Low | T33: =IF(P33>=3000,"High",IF(P33>=1500,"Medium","Low")) -> Low | V33: Football | W33: BrandD | X33: 9 | Y33: 2525.23
A34: 10033 | B34: 1459 | C34: 45129 | D34: 45130 | E34: Pune | F34: Karnataka | G34: Mobile App | H34: UPI | I34: Books | J34: Comics | K34: BrandC | L34: 7 | M34: 3363.18 | N34: =L34*M34 -> 23542.26 | O34: 20 | P34: =N34*O34/100 -> 4708.452 | Q34: =N34-P34 -> 18833.808 | R34: =IF(Q34>=10000,"High","Low") -> High | S34: {=_xlfn.IFS(L34>=8,"High",L34>=5,"Medium",L34<5,"Low")} -> Medium | T34: =IF(P34>=3000,"High",IF(P34>=1500,"Medium","Low")) -> High | V34: Sneakers | W34: BrandE | X34: 6 | Y34: 3474.34
A35: 10034 | B35: 1313 | C35: 45182 | D35: 45191 | E35: Bengaluru | F35: Tamil Nadu | G35: Marketplace | H35: Debit Card | I35: Fashion | J35: T-Shirt | K35: BrandB | L35: 6 | M35: 1529.59 | N35: =L35*M35 -> 9177.54 | O35: 0 | P35: =N35*O35/100 -> 0 | Q35: =N35-P35 -> 9177.54 | R35: =IF(Q35>=10000,"High","Low") -> Low | S35: {=_xlfn.IFS(L35>=8,"High",L35>=5,"Medium",L35<5,"Low")} -> Medium | T35: =IF(P35>=3000,"High",IF(P35>=1500,"Medium","Low")) -> Low | V35: Yoga Mat | W35: BrandA | Y35: 1008.79
A36: 10035 | B36: 1021 | C36: 45012 | D36: 45013 | E36: Hyderabad | F36: West Bengal | G36: Marketplace | H36: UPI | I36: Fashion | J36: T-Shirt | K36: BrandB | L36: 7 | M36: 3664.64 | N36: =L36*M36 -> 25652.48 | O36: 5 | P36: =N36*O36/100 -> 1282.624 | Q36: =N36-P36 -> 24369.856 | R36: =IF(Q36>=10000,"High","Low") -> High | S36: {=_xlfn.IFS(L36>=8,"High",L36>=5,"Medium",L36<5,"Low")} -> Medium | T36: =IF(P36>=3000,"High",IF(P36>=1500,"Medium","Low")) -> Low | V36: Jacket | W36: BrandA | X36: 7 | Y36: 3511.47
A37: 10036 | B37: 1252 | C37: 45076 | D37: 45084 | E37: Delhi | F37: Karnataka | G37: Mobile App | H37: Net Banking | I37: Sports | J37: Football | K37: BrandD | L37: 5 | M37: 2327.9 | N37: =L37*M37 -> 11639.5 | O37: 0 | P37: =N37*O37/100 -> 0 | Q37: =N37-P37 -> 11639.5 | R37: =IF(Q37>=10000,"High","Low") -> High | S37: {=_xlfn.IFS(L37>=8,"High",L37>=5,"Medium",L37<5,"Low")} -> Medium | T37: =IF(P37>=3000,"High",IF(P37>=1500,"Medium","Low")) -> Low | V37: Bedsheet | W37: BrandE | Y37: 3189.55
A38: 10037 | B38: 1747 | C38: 45161 | D38: 45165 | E38: Kolkata | F38: Delhi | G38: Website | H38: Credit Card | I38: Home & Kitchen | J38: Curtains | K38: BrandA | L38: 4 | M38: 853.29 | N38: =L38*M38 -> 3413.16 | O38: 5 | P38: =N38*O38/100 -> 170.658 | Q38: =N38-P38 -> 3242.502 | R38: =IF(Q38>=10000,"High","Low") -> Low | S38: {=_xlfn.IFS(L38>=8,"High",L38>=5,"Medium",L38<5,"Low")} -> Low | T38: =IF(P38>=3000,"High",IF(P38>=1500,"Medium","Low")) -> Low | V38: Sneakers | W38: BrandC | X38: 5 | Y38: 3030.42
A39: 10038 | B39: 1856 | C39: 45271 | D39: 45280 | E39: Pune | F39: West Bengal | G39: Website | H39: Net Banking | I39: Electronics | J39: Laptop | K39: BrandB | L39: 7 | M39: 687.46 | N39: =L39*M39 -> 4812.22 | O39: 20 | P39: =N39*O39/100 -> 962.444 | Q39: =N39-P39 -> 3849.776 | R39: =IF(Q39>=10000,"High","Low") -> Low | S39: {=_xlfn.IFS(L39>=8,"High",L39>=5,"Medium",L39<5,"Low")} -> Medium | T39: =IF(P39>=3000,"High",IF(P39>=1500,"Medium","Low")) -> Low | V39: Sneakers | W39: BrandB | X39: 4 | Y39: 2310.83
A40: 10039 | B40: 1560 | C40: 44948 | D40: 44953 | E40: Bengaluru | F40: Telangana | G40: Mobile App | H40: Credit Card | I40: Fashion | J40: T-Shirt | K40: BrandC | L40: 7 | M40: 2369.42 | N40: =L40*M40 -> 16585.94 | O40: 15 | P40: =N40*O40/100 -> 2487.891 | Q40: =N40-P40 -> 14098.049 | R40: =IF(Q40>=10000,"High","Low") -> High | S40: {=_xlfn.IFS(L40>=8,"High",L40>=5,"Medium",L40<5,"Low")} -> Medium | T40: =IF(P40>=3000,"High",IF(P40>=1500,"Medium","Low")) -> Medium
...

Sheet Sheet7
A1: Order ID | B1: Customer ID | C1: Order Date | D1: Ship Date | E1: City | F1: State | G1: Sales Channel | H1: Payment Method | I1: Product Category | J1: Product Name | K1: Brand | L1: Units Sold | M1: Unit Price
A2: 10403 | B2: 1152 | C2: 45035 | D2: 45037 | E2: Delhi | F2: Karnataka | G2: Website | H2: UPI | I2: Sports | J2: Yoga Mat | K2: BrandA | L2: 1 | M2: 2743.75 | O2: City | Q2: Sales Channel | S2: Unit Price
A3: 10406 | B3: 1895 | C3: 45195 | D3: 45204 | E3: Delhi | F3: West Bengal | G3: Marketplace | H3: UPI | I3: Electronics | J3: Smartwatch | K3: BrandA | L3: 1 | M3: 2044.41 | O3: Kolkata | Q3: Mobile App | S3: >1000
A4: 10460 | B4: 1515 | C4: 45215 | D4: 45221 | E4: Pune | F4: West Bengal | G4: Website | H4: Debit Card | I4: Electronics | J4: Headphones | K4: BrandA | L4: 1 | M4: 445.38
A5: 10020 | B5: 1130 | C5: 45194 | D5: 45203 | E5: Mumbai | F5: Karnataka | G5: Mobile App | H5: Credit Card | I5: Electronics | J5: Smartwatch | K5: BrandA | L5: 2 | M5: 3959.31
A6: 10102 | B6: 1161 | C6: 44996 | D6: 45002 | E6: Kolkata | F6: Maharashtra | G6: Marketplace | H6: Debit Card | I6: Fashion | J6: Jacket | K6: BrandA | L6: 2 | M6: 1859.03
A7: 10108 | B7: 1815 | C7: 45037 | D7: 45045 | E7: Chennai | F7: West Bengal | G7: Website | H7: Credit Card | I7: Sports | J7: Yoga Mat | K7: BrandA | L7: 2 | M7: 564.31
A8: 10004 | B8: 1270 | C8: 45079 | D8: 45087 | E8: Bengaluru | F8: West Bengal | G8: Website | H8: Cash on Delivery | I8: Sports | J8: Yoga Mat | K8: BrandA | L8: 1 | M8: 1008.79 | O8: Order ID | P8: Customer ID | Q8: Order Date | R8: Ship Date | S8: City | T8: State | U8: Sales Channel | V8: Payment Method | W8: Product Category | X8: Product Name | Y8: Brand | Z8: Units Sold | AA8: Unit Price
A9: 10073 | B9: 1564 | C9: 45055 | D9: 45063 | E9: Hyderabad | F9: Delhi | G9: Mobile App | H9: Debit Card | I9: Electronics | J9: Smartphone | K9: BrandA | L9: 1 | M9: 3037.61 | O9: 10102 | P9: 1161 | Q9: 44996 | R9: 45002 | S9: Kolkata | T9: Maharashtra | U9: Marketplace | V9: Debit Card | W9: Fashion | X9: Jacket | Y9: BrandA | Z9: 2 | AA9: 1859.03
A10: 10138 | B10: 1128 | C10: 45088 | D10: 45093 | E10: Pune | F10: West Bengal | G10: Mobile App | H10: Cash on Delivery | I10: Beauty | J10: Shampoo | K10: BrandA | L10: 1 | M10: 912.67 | O10: 10027 | P10: 1805 | Q10: 45286 | R10: 45290 | S10: Kolkata | T10: Telangana | U10: Website | V10: Cash on Delivery | W10: Books | X10: Fiction Novel | Y10: BrandA | Z10: 3 | AA10: 3599.15
A11: 10232 | B11: 1639 | C11: 44962 | D11: 44969 | E11: Pune | F11: West Bengal | G11: Mobile App | H11: Credit Card | I11: Books | J11: Comics | K11: BrandA | L11: 1 | M11: 2250.49 | O11: 10037 | P11: 1747 | Q11: 45161 | R11: 45165 | S11: Kolkata | T11: Delhi | U11: Website | V11: Credit Card | W11: Home & Kitchen | X11: Curtains | Y11: BrandA | Z11: 4 | AA11: 853.29
A12: 10350 | B12: 1640 | C12: 45180 | D12: 45185 | E12: Chennai | F12: Telangana | G12: Mobile App | H12: UPI | I12: Books | J12: Textbook | K12: BrandA | L12: 1 | M12: 3708.38 | O12: 10112 | P12: 1726 | Q12: 45153 | R12: 45154 | S12: Kolkata | T12: Telangana | U12: Marketplace | V12: Credit Card | W12: Sports | X12: Yoga Mat | Y12: BrandA | Z12: 4 | AA12: 1110.59
A13: 10190 | B13: 1857 | C13: 45185 | D13: 45187 | E13: Bengaluru | F13: Maharashtra | G13: Marketplace | H13: Debit Card | I13: Electronics | J13: Smartwatch | K13: BrandA | L13: 2 | M13: 1372.59 | O13: 10127 | P13: 1379 | Q13: 44930 | R13: 44935 | S13: Kolkata | T13: Maharashtra | U13: Website | V13: Credit Card | W13: Fashion | X13: Jacket | Y13: BrandA | Z13: 6 | AA13: 1846.21
A14: 10192 | B14: 1891 | C14: 45039 | D14: 45042 | E14: Chennai | F14: West Bengal | G14: Marketplace | H14: Cash on Delivery | I14: Beauty | J14: Perfume | K14: BrandA | L14: 2 | M14: 487.23 | O14: 10216 | P14: 1085 | Q14: 45221 | R14: 45227 | S14: Kolkata | T14: Tamil Nadu | U14: Website | V14: Credit Card | W14: Books | X14: Biography | Y14: BrandA | Z14: 6 | AA14: 809.49
A15: 10305 | B15: 1438 | C15: 44991 | D15: 44993 | E15: Mumbai | F15: Telangana | G15: Mobile App | H15: Cash on Delivery | I15: Fashion | J15: T-Shirt | K15: BrandA | L15: 2 | M15: 3256.02 | O15: 10303 | P15: 1246 | Q15: 45124 | R15: 45125 | S15: Kolkata | T15: West Bengal | U15: Mobile App | V15: Debit Card | W15: Books | X15: Biography | Y15: BrandA | Z15: 6 | AA15: 257.2
A16: 10332 | B16: 1954 | C16: 44946 | D16: 44955 | E16: Chennai | F16: Tamil Nadu | G16: Mobile App | H16: Net Banking | I16: Books | J16: Biography | K16: BrandA | L16: 2 | M16: 1335.36 | O16: 10005 | P16: 1106 | Q16: 45241 | R16: 45244 | S16: Kolkata | T16: Karnataka | U16: Marketplace | V16: Credit Card | W16: Fashion | X16: Jacket | Y16: BrandA | Z16: 7 | AA16: 3511.47
A17: 10372 | B17: 1651 | C17: 45164 | D17: 45167 | E17: Delhi | F17: Tamil Nadu | G17: Website | H17: Cash on Delivery | I17: Electronics | J17: Laptop | K17: BrandA | L17: 2 | M17: 3957.02 | O17: 10143 | P17: 1498 | Q17: 44986 | R17: 44993 | S17: Kolkata | T17: Maharashtra | U17: Marketplace | V17: Debit Card | W17: Books | X17: Fiction Novel | Y17: BrandA | Z17: 7 | AA17: 3680.23
A18: 10444 | B18: 1437 | C18: 44960 | D18: 44969 | E18: Hyderabad | F18: Karnataka | G18: Marketplace | H18: Credit Card | I18: Fashion | J18: Sneakers | K18: BrandA | L18: 2 | M18: 3904.44 | O18: 10289 | P18: 1854 | Q18: 45012 | R18: 45014 | S18: Kolkata | T18: Maharashtra | U18: Mobile App | V18: Debit Card | W18: Books | X18: Fiction Novel | Y18: BrandA | Z18: 7 | AA18: 1396.71
A19: 10021 | B19: 1661 | C19: 45159 | D19: 45163 | E19: Mumbai | F19: West Bengal | G19: Website | H19: Credit Card | I19: Beauty | J19: Lipstick | K19: BrandA | L19: 3 | M19: 2361.58 | O19: 10330 | P19: 1659 | Q19: 44958 | R19: 44966 | S19: Kolkata | T19: Maharashtra | U19: Mobile App | V19: UPI | W19: Beauty | X19: Face Cream | Y19: BrandA | Z19: 7 | AA19: 3978.5
A20: 10027 | B20: 1805 | C20: 45286 | D20: 45290 | E20: Kolkata | F20: Telangana | G20: Website | H20: Cash on Delivery | I20: Books | J20: Fiction Novel | K20: BrandA | L20: 3 | M20: 3599.15 | O20: 10041 | P20: 1058 | Q20: 45211 | R20: 45220 | S20: Kolkata | T20: Delhi | U20: Mobile App | V20: Debit Card | W20: Beauty | X20: Face Cream | Y20: BrandA | Z20: 8 | AA20: 3158.8
... A70: 10171 | B70: 1986 | C70: 45227 | D70: 45228 | E70: Chennai | F70: Telangana | G70: Website | H70: Credit Card | I70: Home & Kitchen | J70: Bedsheet | K70: BrandA | L70: 8 | M70: 3795.01 | O70: 10057 | P70: 1504 | Q70: 45117 | R70: 45122 | S70: Kolkata | T70: West Bengal | U70: Mobile App | V70: Debit Card | W70: Books | X70: Fiction Novel | Y70: BrandE | Z70: 9 | AA70: 1012.33
A71: 10196 | B71: 1863 | C71: 45124 | D71: 45133 | E71: Kolkata | F71: West Bengal | G71: Marketplace | H71: UPI | I71: Beauty | J71: Shampoo | K71: BrandA | L71: 8 | M71: 2561.86
A72: 10220 | B72: 1556 | C72: 45026 | D72: 45035 | E72: Kolkata | F72: Delhi | G72: Website | H72: Credit Card | I72: Home & Kitchen | J72: Curtains | K72: BrandA | L72: 8 | M72: 3240.98
A73: 10015 | B73: 1087 | C73: 45048 | D73: 45057 | E73: Hyderabad | F73: Tamil Nadu | G73: Website | H73: Credit Card | I73: Beauty | J73: Shampoo | K73: BrandA | L73: 9 | M73: 705.59
A74: 10179 | B74: 1768 | C74: 44973 | D74: 44976 | E74: Kolkata | F74: Delhi | G74: Marketplace | H74: Debit Card | I74: Fashion | J74: Sneakers | K74: BrandA | L74: 9 | M74: 388.26 | P74: Order ID | Q74: Customer ID | R74: Order Date | S74: Ship Date | T74: City | U74: State | V74: Sales Channel | W74: Payment Method | X74: Product Category | Y74: Product Name | Z74: Brand | AA74: Units Sold | AB74: Unit Price
A75: 10355 | B75: 1945 | C75: 45188 | D75: 45191 | E75: Kolkata | F75: Tamil Nadu | G75: Marketplace | H75: Cash on Delivery | I75: Beauty | J75: Shampoo | K75: BrandA | L75: 9 | M75: 2632.88 | P75: 10020 | Q75: 1130 | R75: 45194 | S75: 45203 | T75: Mumbai | U75: Karnataka | V75: Mobile App | W75: Credit Card | X75: Electronics | Y75: Smartwatch | Z75: BrandA | AA75: 2 | AB75: 3959.31
A76: 10356 | B76: 1150 | C76: 45093 | D76: 45102 | E76: Delhi | F76: Karnataka | G76: Marketplace | H76: Net Banking | I76: Fashion | J76: T-Shirt | K76: BrandA | L76: 9 | M76: 1259.77 | P76: 10073 | Q76: 1564 | R76: 45055 | S76: 45063 | T76: Hyderabad | U76: Delhi | V76: Mobile App | W76: Debit Card | X76: Electronics | Y76: Smartphone | Z76: BrandA | AA76: 1 | AB76: 3037.61
A77: 10045 | B77: 1699 | C77: 45139 | D77: 45147 | E77: Bengaluru | F77: Delhi | G77: Mobile App | H77: Debit Card | I77: Sports | J77: Cricket Bat | K77: BrandB | L77: 1 | M77: 2764.92 | P77: 10138 | Q77: 1128 | R77: 45088 | S77: 45093 | T77: Pune | U77: West Bengal | V77: Mobile App | W77: Cash on Delivery | X77: Beauty | Y77: Shampoo | Z77: BrandA | AA77: 1 | AB77: 912.67
A78: 10047 | B78: 1782 | C78: 44976 | D78: 44985 | E78: Hyderabad | F78: Telangana | G78: Mobile App | H78: Credit Card | I78: Books | J78: Textbook | K78: BrandB | L78: 1 | M78: 1769.93 | P78: 10232 | Q78: 1639 | R78: 44962 | S78: 44969 | T78: Pune | U78: West Bengal | V78: Mobile App | W78: Credit Card | X78: Books | Y78: Comics | Z78: BrandA | AA78: 1 | AB78: 2250.49
A79: 10152 | B79: 1230 | C79: 45043 | D79: 45050 | E79: Kolkata | F79: Delhi | G79: Website | H79: UPI | I79: Beauty | J79: Lipstick | K79: BrandB | L79: 1 | M79: 3249.11 | P79: 10350 | Q79: 1640 | R79: 45180 | S79: 45185 | T79: Chennai | U79: Telangana | V79: Mobile App | W79: UPI | X79: Books | Y79: Textbook | Z79: BrandA | AA79: 1 | AB79: 3708.38
A80: 10186 | B80: 1794 | C80: 45251 | D80: 45254 | E80: Kolkata | F80: Telangana | G80: Marketplace | H80: Debit Card | I80: Beauty | J80: Lipstick | K80: BrandB | L80: 1 | M80: 508.81 | P80: 10305 | Q80: 1438 | R80: 44991 | S80: 44993 | T80: Mumbai | U80: Telangana | V80: Mobile App | W80: Cash on Delivery | X80: Fashion | Y80: T-Shirt | Z80: BrandA | AA80: 2 | AB80: 3256.02
A81: 10233 | B81: 1505 | C81: 45139 | D81: 45143 | E81: Delhi | F81: Telangana | G81: Mobile App | H81: UPI | I81: Home & Kitchen | J81: Curtains | K81: BrandB | L81: 1 | M81: 556.53 | P81: 10332 | Q81: 1954 | R81: 44946 | S81: 44955 | T81: Chennai | U81: Tamil Nadu | V81: Mobile App | W81: Net Banking | X81: Books | Y81: Biography | Z81: BrandA | AA81: 2 | AB81: 1335.36
A82: 10267 | B82: 1691 | C82: 45074 | D82: 45079 | E82: Hyderabad | F82: Karnataka | G82: Marketplace | H82: UPI | I82: Beauty | J82: Shampoo | K82: BrandB | L82: 1 | M82: 900.78 | P82: 10188 | Q82: 1206 | R82: 45064 | S82: 45070 | T82: Hyderabad | U82: Maharashtra | V82: Mobile App | W82: Debit Card | X82: Beauty | Y82: Shampoo | Z82: BrandA | AA82: 3 | AB82: 778.85
A83: 10309 | B83: 1400 | C83: 44928 | D83: 44936 | E83: Bengaluru | F83: West Bengal | G83: Marketplace | H83: UPI | I83: Electronics | J83: Smartwatch | K83: BrandB | L83: 1 | M83: 2740.46 | P83: 10339 | Q83: 1147 | R83: 45005 | S83: 45012 | T83: Chennai | U83: Maharashtra | V83: Mobile App | W83: Debit Card | X83: Fashion | Y83: Sneakers | Z83: BrandA | AA83: 4 | AB83: 3708.51
A84: 10329 | B84: 1770 | C84: 44975 | D84: 44976 | E84: Hyderabad | F84: Karnataka | G84: Mobile App | H84: UPI | I84: Sports | J84: Football | K84: BrandB | L84: 1 | M84: 3171.36 | P84: 10053 | Q84: 1875 | R84: 45115 | S84: 45118 | T84: Mumbai | U84: Delhi | V84: Mobile App | W84: Cash on Delivery | X84: Beauty | Y84: Face Cream | Z84: BrandA | AA84: 5 | AB84: 2534.07
A85: 10359 | B85: 1297 | C85: 45104 | D85: 45105 | E85: Delhi | F85: Telangana | G85: Mobile App | H85: Debit Card | I85: Fashion | J85: T-Shirt | K85: BrandB | L85: 1 | M85: 202.49 | P85: 10184 | Q85: 1397 | R85: 45063 | S85: 45072 | T85: Pune | U85: Maharashtra | V85: Mobile App | W85: UPI | X85: Beauty | Y85: Face Cream | Z85: BrandA | AA85: 5 | AB85: 2125.75
A86: 10390 | B86: 1586 | C86: 45102 | D86: 45103 | E86: Hyderabad | F86: Maharashtra | G86: Website | H86: Cash on Delivery | I86: Fashion | J86: T-Shirt | K86: BrandB | L86: 1 | M86: 2430.36 | P86: 10215 | Q86: 1242 | R86: 45157 | S86: 45162 | T86: Chennai | U86: Delhi | V86: Mobile App | W86: Debit Card | X86: Sports | Y86: Football | Z86: BrandA | AA86: 5 | AB86: 633.43
... A195: 10025 | B195: 1491 | C195: 45052 | D195: 45061 | E195: Kolkata | F195: Karnataka | G195: Marketplace | H195: UPI | I195: Books | J195: Comics | K195: BrandC | L195: 6 | M195: 3018.94 | P195: 10093 | Q195: 1565 | R195: 44980 | S195: 44982 | T195: Hyderabad | U195: West Bengal | V195: Mobile App | W195: Net Banking | X195: Beauty | Y195: Lipstick | Z195: BrandE | AA195: 9 | AB195: 1938.76
A196: 10056 | B196: 1831 | C196: 44929 | D196: 44934 | E196: Kolkata | F196: West Bengal | G196: Mobile App | H196: Net Banking | I196: Books | J196: Textbook | K196: BrandC | L196: 6 | M196: 3402.72
A197: 10156 | B197: 1200 | C197: 45099 | D197: 45106 | E197: Hyderabad | F197: Karnataka | G197: Website | H197: Credit Card | I197: Books | J197: Comics | K197: BrandC | L197: 6 | M197: 445.71
...

Sheet Sheet8
A1: Order ID | B1: Customer ID | C1: Order Date | D1: Ship Date | E1: City | F1: State | G1: Sales Channel | H1: Payment Method | I1: Product Category | J1: Product Name | K1: Brand | L1: Units Sold | M1: Unit Price | O1: Order ID | P1: Customer ID | Q1: Order Date | R1: Ship Date | S1: City | T1: State | U1: Sales Channel | V1: Payment Method | W1: Product Category | X1: Product Name | Y1: Brand | Z1: Units Sold | AA1: Unit Price
A2: 10102 | B2: 1161 | C2: 44996 | D2: 45002 | E2: Kolkata | F2: Maharashtra | G2: Marketplace | H2: Debit Card | I2: Fashion | J2: Jacket | K2: BrandA | L2: 2 | M2: 1859.03 | O2: 10020 | P2: 1130 | Q2: 45194 | R2: 45203 | S2: Mumbai | T2: Karnataka | U2: Mobile App | V2: Credit Card | W2: Electronics | X2: Smartwatch | Y2: BrandA | Z2: 2 | AA2: 3959.31
A3: 10027 | B3: 1805 | C3: 45286 | D3: 45290 | E3: Kolkata | F3: Telangana | G3: Website | H3: Cash on Delivery | I3: Books | J3: Fiction Novel | K3: BrandA | L3: 3 | M3: 3599.15 | O3: 10073 | P3: 1564 | Q3: 45055 | R3: 45063 | S3: Hyderabad | T3: Delhi | U3: Mobile App | V3: Debit Card | W3: Electronics | X3: Smartphone | Y3: BrandA | Z3: 1 | AA3: 3037.61
A4: 10037 | B4: 1747 | C4: 45161 | D4: 45165 | E4: Kolkata | F4: Delhi | G4: Website | H4: Credit Card | I4: Home & Kitchen | J4: Curtains | K4: BrandA | L4: 4 | M4: 853.29 | O4: 10138 | P4: 1128 | Q4: 45088 | R4: 45093 | S4: Pune | T4: West Bengal | U4: Mobile App | V4: Cash on Delivery | W4: Beauty | X4: Shampoo | Y4: BrandA | Z4: 1 | AA4: 912.67
A5: 10112 | B5: 1726 | C5: 45153 | D5: 45154 | E5: Kolkata | F5: Telangana | G5: Marketplace | H5: Credit Card | I5: Sports | J5: Yoga Mat | K5: BrandA | L5: 4 | M5: 1110.59 | O5: 10232 | P5: 1639 | Q5: 44962 | R5: 44969 | S5: Pune | T5: West Bengal | U5: Mobile App | V5: Credit Card | W5: Books | X5: Comics | Y5: BrandA | Z5: 1 | AA5: 2250.49
A6: 10127 | B6: 1379 | C6: 44930 | D6: 44935 | E6: Kolkata | F6: Maharashtra | G6: Website | H6: Credit Card | I6: Fashion | J6: Jacket | K6: BrandA | L6: 6 | M6: 1846.21 | O6: 10350 | P6: 1640 | Q6: 45180 | R6: 45185 | S6: Chennai | T6: Telangana | U6: Mobile App | V6: UPI | W6: Books | X6: Textbook | Y6: BrandA | Z6: 1 | AA6: 3708.38
A7: 10216 | B7: 1085 | C7: 45221 | D7: 45227 | E7: Kolkata | F7: Tamil Nadu | G7: Website | H7: Credit Card | I7: Books | J7: Biography | K7: BrandA | L7: 6 | M7: 809.49 | O7: 10305 | P7: 1438 | Q7: 44991 | R7: 44993 | S7: Mumbai | T7: Telangana | U7: Mobile App | V7: Cash on Delivery | W7: Fashion | X7: T-Shirt | Y7: BrandA | Z7: 2 | AA7: 3256.02
A8: 10303 | B8: 1246 | C8: 45124 | D8: 45125 | E8: Kolkata | F8: West Bengal | G8: Mobile App | H8: Debit Card | I8: Books | J8: Biography | K8: BrandA | L8: 6 | M8: 257.2 | O8: 10332 | P8: 1954 | Q8: 44946 | R8: 44955 | S8: Chennai | T8: Tamil Nadu | U8: Mobile App | V8: Net Banking | W8: Books | X8: Biography | Y8: BrandA | Z8: 2 | AA8: 1335.36
A9: 10005 | B9: 1106 | C9: 45241 | D9: 45244 | E9: Kolkata | F9: Karnataka | G9: Marketplace | H9: Credit Card | I9: Fashion | J9: Jacket | K9: BrandA | L9: 7 | M9: 3511.47 | O9: 10188 | P9: 1206 | Q9: 45064 | R9: 45070 | S9: Hyderabad | T9: Maharashtra | U9: Mobile App | V9: Debit Card | W9: Beauty | X9: Shampoo | Y9: BrandA | Z9: 3 | AA9: 778.85
A10: 10143 | B10: 1498 | C10: 44986 | D10: 44993 | E10: Kolkata | F10: Maharashtra | G10: Marketplace | H10: Debit Card | I10: Books | J10: Fiction Novel | K10: BrandA | L10: 7 | M10: 3680.23 | O10: 10339 | P10: 1147 | Q10: 45005 | R10: 45012 | S10: Chennai | T10: Maharashtra | U10: Mobile App | V10: Debit Card | W10: Fashion | X10: Sneakers | Y10: BrandA | Z10: 4 | AA10: 3708.51
A11: 10289 | B11: 1854 | C11: 45012 | D11: 45014 | E11: Kolkata | F11: Maharashtra | G11: Mobile App | H11: Debit Card | I11: Books | J11: Fiction Novel | K11: BrandA | L11: 7 | M11: 1396.71 | O11: 10053 | P11: 1875 | Q11: 45115 | R11: 45118 | S11: Mumbai | T11: Delhi | U11: Mobile App | V11: Cash on Delivery | W11: Beauty | X11: Face Cream | Y11: BrandA | Z11: 5 | AA11: 2534.07
A12: 10330 | B12: 1659 | C12: 44958 | D12: 44966 | E12: Kolkata | F12: Maharashtra | G12: Mobile App | H12: UPI | I12: Beauty | J12: Face Cream | K12: BrandA | L12: 7 | M12: 3978.5 | O12: 10184 | P12: 1397 | Q12: 45063 | R12: 45072 | S12: Pune | T12: Maharashtra | U12: Mobile App | V12: UPI | W12: Beauty | X12: Face Cream | Y12: BrandA | Z12: 5 | AA12: 2125.75
A13: 10041 | B13: 1058 | C13: 45211 | D13: 45220 | E13: Kolkata | F13: Delhi | G13: Mobile App | H13: Debit Card | I13: Beauty | J13: Face Cream | K13: BrandA | L13: 8 | M13: 3158.8 | O13: 10215 | P13: 1242 | Q13: 45157 | R13: 45162 | S13: Chennai | T13: Delhi | U13: Mobile App | V13: Debit Card | W13: Sports | X13: Football | Y13: BrandA | Z13: 5 | AA13: 633.43
... A63: 10057 | B63: 1504 | C63: 45117 | D63: 45122 | E63: Kolkata | F63: West Bengal | G63: Mobile App | H63: Debit Card | I63: Books | J63: Fiction Novel | K63: BrandE | L63: 9 | M63: 1012.33 | O63: 10254 | P63: 1676 | Q63: 45010 | R63: 45012 | S63: Pune | T63: Delhi | U63: Mobile App | V63: Net Banking | W63: Beauty | X63: Face Cream | Y63: BrandC | Z63: 2 | AA63: 2711.66
O64: 10455 | P64: 1480 | Q64: 45034 | R64: 45036 | S64: Chennai | T64: West Bengal | U64: Mobile App | V64: Credit Card | W64: Beauty | X64: Face Cream | Y64: BrandC | Z64: 2 | AA64: 1374.23
O65: 10485 | P65: 1992 | Q65: 45228 | R65: 45237 | S65: Delhi | T65: Delhi | U65: Mobile App | V65: Net Banking | W65: Home & Kitchen | X65: Bedsheet | Y65: BrandC | Z65: 2 | AA65: 1294.84
O66: 10244 | P66: 1627 | Q66: 45032 | R66: 45038 | S66: Bengaluru | T66: West Bengal | U66: Mobile App | V66: UPI | W66: Beauty | X66: Shampoo | Y66: BrandC | Z66: 3 | AA66: 800.89
O67: 10441 | P67: 1229 | Q67: 45116 | R67: 45119 | S67: Delhi | T67: Tamil Nadu | U67: Mobile App | V67: Net Banking | W67: Fashion | X67: Jeans | Y67: BrandC | Z67: 3 | AA67: 2189.4
O68: 10175 | P68: 1612 | Q68: 45074 | R68: 45081 | S68: Delhi | T68: Telangana | U68: Mobile App | V68: Credit Card | W68: Fashion | X68: Sneakers | Y68: BrandC | Z68: 4 | AA68: 2836.21
O69: 10197 | P69: 1742 | Q69: 45263 | R69: 45266 | S69: Delhi | T69: Karnataka | U69: Mobile App | V69: Cash on Delivery | W69: Electronics | X69: Smartphone | Y69: BrandC | Z69: 4 | AA69: 1256.21
O70: 10007 | P70: 1700 | Q70: 45050 | R70: 45054 | S70: Bengaluru | T70: Telangana | U70: Mobile App | V70: UPI | W70: Fashion | X70: Sneakers | Y70: BrandC | Z70: 5 | AA70: 3030.42
O71: 10107 | P71: 1862 | Q71: 45058 | R71: 45064 | S71: Mumbai | T71: Karnataka | U71: Mobile App | V71: UPI | W71: Beauty | X71: Perfume | Y71: BrandC | Z71: 5 | AA71: 1063.01
O72: 10198 | P72: 1240 | Q72: 45291 | R72: 45292 | S72: Bengaluru | T72: Telangana | U72: Mobile App | V72: Net Banking | W72: Home & Kitchen | X72: Cookware Set | Y72: BrandC | Z72: 5 | AA72: 1227.02
O73: 10226 | P73: 1619 | Q73: 45290 | R73: 45291 | S73: Kolkata | T73: Karnataka | U73: Mobile App | V73: Net Banking | W73: Electronics | X73: Laptop | Y73: BrandC | Z73: 5 | AA73: 620.13
O74: 10494 | P74: 1322 | Q74: 45151 | R74: 45154 | S74: Kolkata | T74: Telangana | U74: Mobile App | V74: UPI | W74: Books | X74: Biography | Y74: BrandC | Z74: 5 | AA74: 529.59
O75: 10056 | P75: 1831 | Q75: 44929 | R75: 44934 | S75: Kolkata | T75: West Bengal | U75: Mobile App | V75: Net Banking | W75: Books | X75: Textbook | Y75: BrandC | Z75: 6 | AA75: 3402.72
... O122: 10093 | P122: 1565 | Q122: 44980 | R122: 44982 | S122: Hyderabad | T122: West Bengal | U122: Mobile App | V122: Net Banking | W122: Beauty | X122: Lipstick | Y122: BrandE | Z122: 9 | AA122: 1938.76

Sheet Sheet9
A1: Batch Code | B1: ILT Hours | C1: ILT %
A2: ANP-D2475 | B2: 118.57 | C2: 0.6854
A3: ANP-D3870 | B3: 26.93 | C3: 0.1557
A4: ANP-D4972 | B4: 33.38 | C4: 0.193
A5: ANP-D2474 | B5: 112.52 | C5: 0.6504
A6: ANP-D4971 | B6: 31.03 | C6: 0.1794
A7: ANP-D3872 | B7: 23.88 | C7: 0.1381

Sheet Sheet16
B13: Name | C13: Sub1 | D13: Sub2 | E13: Sub3
B14: Soham | C14: 65 | D14: 68 | E14: 90
B15: Amiya | C15: 45 | D15: 64 | E15: 98
B16: Ajay | C16: 56 | D16: 89 | E16: 73
B17: Nisha | C17: 83 | D17: 87 | E17: 51
B18: Sahil | C18: 78 | D18: 90 | E18: 68
B19: Riya | C19: 60 | D19: 87 | E19: 93
B20: Nilay | C20: 65 | D20: 98 | E20: 78

Sheet Sheet17
G2: Name | H2: Sub1 | I2: Sub2 | J2: Sub3
G3: Soham | H3: 65 | I3: 68 | J3: 100
G4: Amiya | H4: 45 | I4: 64 | J4: 98
G5: Ajay | H5: 56 | I5: 89 | J5: 73
G6: Nisha | H6: 83 | I6: 87 | J6: 51
G7: Sahil | H7: 78 | I7: 90 | J7: 68
G8: Riya | H8: 60 | I8: 87 | J8: 93
G9: Nilay | H9: 65 | I9: 98 | J9: 78

Sheet Sheet18
E10: Name | F10: Sub1 | G10: Sub2 | H10: Sub3
E11: Soham | F11: 65 | G11: 68 | H11: 90
E12: Amiya | F12: 45 | G12: 64 | H12: 98
E13: Ajay | F13: 56 | G13: 89 | H13: 73
E14: Nisha | F14: 83 | G14: 87 | H14: 51
E15: Sahil | F15: 78 | G15: 90 | H15: 68
E16: Riya | F16: 60 | G16: 87 | H16: 93
E17: Nilay | F17: 65 | G17: 98 | H17: 78

Sheet Sheet19
B2: =SUM(Sheet16:Sheet18!B2) -> 0 | C2: =SUM(Sheet16:Sheet18!C2) -> 0 | D2: =SUM(Sheet16:Sheet18!D2) -> 0
B3: =SUM(Sheet16:Sheet18!B3) -> 0 | C3: =SUM(Sheet16:Sheet18!C3) -> 0 | D3: =SUM(Sheet16:Sheet18!D3) -> 0
B4: =SUM(Sheet16:Sheet18!B4) -> 0 | C4: =SUM(Sheet16:Sheet18!C4) -> 0 | D4: =SUM(Sheet16:Sheet18!D4) -> 0
B5: =SUM(Sheet16:Sheet18!B5) -> 0 | C5: =SUM(Sheet16:Sheet18!C5) -> 0 | D5: =SUM(Sheet16:Sheet18!D5) -> 0
B6: =SUM(Sheet16:Sheet18!B6) -> 0 | C6: =SUM(Sheet16:Sheet18!C6) -> 0 | D6: =SUM(Sheet16:Sheet18!D6) -> 0 | J6: Sub1 | K6: Sub2 | L6: Sub3
I7: Anp-D4972_Class Work | J7: =Sheet16!$C$14 -> 65 | K7: =Sheet16!$D$14 -> 68 | L7: =Sheet16!$E$14 -> 90
I8: Anp-D4972_Class Work | J8: =Sheet17!$H$3 -> 65 | K8: =Sheet17!$I$3 -> 68 | L8: =Sheet17!$J$3 -> 100
I9: Anp-D4972_Class Work | J9: =Sheet18!$F$11 -> 65 | K9: =Sheet18!$G$11 -> 68 | L9: =Sheet18!$H$11 -> 90
B10: =SUM(Sheet16:Sheet18!B7) -> 0 | C10: =SUM(Sheet16:Sheet18!C7) -> 0 | D10: =SUM(Sheet16:Sheet18!D7) -> 0 | H10: Soham | J10: =SUM(J7:J9) -> 195 | K10: =SUM(K7:K9) -> 204 | L10: =SUM(L7:L9) -> 280
I11: Anp-D4972_Class Work | J11: =Sheet16!$C$15 -> 45 | K11: =Sheet16!$D$15 -> 64 | L11: =Sheet16!$E$15 -> 98
I12: Anp-D4972_Class Work | J12: =Sheet17!$H$4 -> 45 | K12: =Sheet17!$I$4 -> 64 | L12: =Sheet17!$J$4 -> 98
I13: Anp-D4972_Class Work | J13: =Sheet18!$F$12 -> 45 | K13: =Sheet18!$G$12 -> 64 | L13: =Sheet18!$H$12 -> 98
H14: Amiya | J14: =SUM(J11:J13) -> 135 | K14: =SUM(K11:K13) -> 192 | L14: =SUM(L11:L13) -> 294
I15: Anp-D4972_Class Work | J15: =Sheet16!$C$16 -> 56 | K15: =Sheet16!$D$16 -> 89 | L15: =Sheet16!$E$16 -> 73
I16: Anp-D4972_Class Work | J16: =Sheet17!$H$5 -> 56 | K16: =Sheet17!$I$5 -> 89 | L16: =Sheet17!$J$5 -> 73
I17: Anp-D4972_Class Work | J17: =Sheet18!$F$13 -> 56 | K17: =Sheet18!$G$13 -> 89 | L17: =Sheet18!$H$13 -> 73
H18: Ajay | J18: =SUM(J15:J17) -> 168 | K18: =SUM(K15:K17) -> 267 | L18: =SUM(L15:L17) -> 219
I19: Anp-D4972_Class Work | J19: =Sheet16!$C$17 -> 83 | K19: =Sheet16!$D$17 -> 87 | L19: =Sheet16!$E$17 -> 51
I20: Anp-D4972_Class Work | J20: =Sheet17!$H$6 -> 83 | K20: =Sheet17!$I$6 -> 87 | L20: =Sheet17!$J$6 -> 51
I21: Anp-D4972_Class Work | J21: =Sheet18!$F$14 -> 83 | K21: =Sheet18!$G$14 -> 87 | L21: =Sheet18!$H$14 -> 51
H22: Nisha | J22: =SUM(J19:J21) -> 249 | K22: =SUM(K19:K21) -> 261 | L22: =SUM(L19:L21) -> 153
I23: Anp-D4972_Class Work | J23: =Sheet16!$C$18 -> 78 | K23: =Sheet16!$D$18 -> 90 | L23: =Sheet16!$E$18 -> 68
I24: Anp-D4972_Class Work | J24: =Sheet17!$H$7 -> 78 | K24: =Sheet17!$I$7 -> 90 | L24: =Sheet17!$J$7 -> 68
I25: Anp-D4972_Class Work | J25: =Sheet18!$F$15 -> 78 | K25: =Sheet18!$G$15 -> 90 | L25: =Sheet18!$H$15 -> 68
H26: Sahil | J26: =SUM(J23:J25) -> 234 | K26: =SUM(K23:K25) -> 270 | L26: =SUM(L23:L25) -> 204
I27: Anp-D4972_Class Work | J27: =Sheet16!$C$19 -> 60 | K27: =Sheet16!$D$19 -> 87 | L27: =Sheet16!$E$19 -> 93
I28: Anp-D4972_Class Work | J28: =Sheet17!$H$8 -> 60 | K28: =Sheet17!$I$8 -> 87 | L28: =Sheet17!$J$8 -> 93
I29: Anp-D4972_Class Work | J29: =Sheet18!$F$16 -> 60 | K29: =Sheet18!$G$16 -> 87 | L29: =Sheet18!$H$16 -> 93
H30: Riya | J30: =SUM(J27:J29) -> 180 | K30: =SUM(K27:K29) -> 261 | L30: =SUM(L27:L29) -> 279
I31: Anp-D4972_Class Work | J31: =Sheet16!$C$20 -> 65 | K31: =Sheet16!$D$20 -> 98 | L31: =Sheet16!$E$20 -> 78
I32: Anp-D4972_Class Work | J32: =Sheet17!$H$9 -> 65 | K32: =Sheet17!$I$9 -> 98 | L32: =Sheet17!$J$9 -> 78
I33: Anp-D4972_Class Work | J33: =Sheet18!$F$17 -> 65 | K33: =Sheet18!$G$17 -> 98 | L33: =Sheet18!$H$17 -> 78
H34: Nilay | J34: =SUM(J31:J33) -> 195 | K34: =SUM(K31:K33) -> 294 | L34: =SUM(L31:L33) -> 234

Sheet Sheet3
C2: Mon | E2: Jan | F2: Mango
C3: Tue | E3: Feb | F3: PineApple
C4: Wed | E4: Mar | F4: Orange | I4: Rose | N4: Mon | P4: Mon
C5: Thu | E5: Apr | F5: Apple | I5: Hibiscus | N5: Tue | P5: Tue
C6: Fri | E6: May | F6: Grape | I6: Mogra | N6: Wed | P6: Wed
C7: Sat | E7: Jun | F7: Mango | I7: Marigold | N7: Thu | P7: Thu
C8: Sun | E8: Jul | F8: PineApple | N8: Fri | P8: Fri
C9: Mon | E9: Aug | F9: Orange | N9: Sat | P9: Mon
C10: Tue | E10: Sep | F10: Apple | K10: Mogra | N10: Sun | P10: Tue
F11: Grape | K11: Marigold | N11: Mon | P11: Wed
K12: Rose | N12: Tue | P12: Thu
K13: Hibiscus | P13: Fri
K14: Mogra
K15: Marigold
K16: Rose
K17: Hibiscus

Sheet Sheet2
A1: Name | B1: Sub1 | C1: Sub2 | D1: Sub3 | E1: Total | F1: Average | G1: Grade
I3: >=90 | J3: A
I4: >=70 | J4: B
I5: >=50 | J5: C
I6: >=40 | J6: Pass
I7: <40 | J7: Fail
I9: Use Nested IF

Sheet Sheet4
A1: Order ID | B1: 10001 | C1: 10002 | D1: 10003 | E1: 10004 | F1: 10005 | G1: 10006 | H1: 10007 | I1: 10008 | J1: 10009 | K1: 10010 | L1: 10011 | M1: 10012 | N1: 10013 | O1: 10014 | P1: 10015 | Q1: 10016 | R1: 10017 | S1: 10018 | T1: 10019 | U1: 10020 | V1: 10021 | W1: 10022 | X1: 10023 | Y1: 10024 | Z1: 10025 | AA1: 10026 | AB1: 10027 | AC1: 10028 | AD1: 10029 | AE1: 10030 | AF1: 10031 | AG1: 10032 | AH1: 10033 | AI1: 10034 | AJ1: 10035 | AK1: 10036 | AL1: 10037 | AM1: 10038 | AN1: 10039 | AO1: 10040 | AP1: 10041 | AQ1: 10042 | AR1: 10043 | AS1: 10044 | AT1: 10045 | AU1: 10046 | AV1: 10047 | AW1: 10048 | AX1: 10049 | AY1: 10050 | AZ1: 10052 | BA1: 10053 | BB1: 10054 | BC1: 10055 | BD1: 10056 | BE1: 10057 | BF1: 10059 | BG1: 10060 | BH1: 10061 | BI1: 10063 | BJ1: 10064 | BK1: 10065 | BL1: 10066 | BM1: 10067 | BN1: 10068 | BO1: 10069 | BP1: 10070 | BQ1: 10071 | BR1: 10072 | BS1: 10073 | BT1: 10074 | BU1: 10075 | BV1: 10076 | BW1: 10077 | BX1: 10079 | BY1: 10080 | BZ1: 10081 | CA1: 10082 | CB1: 10083 | CC1: 10084 | CD1: 10085 | CE1: 10086 | CF1: 10087 | CG1: 10088 | CH1: 10091 | CI1: 10092 | CJ1: 10093 | CK1: 10094 | CL1: 10095 | CM1: 10096 | CN1: 10097 | CO1: 10098 | CP1: 10099 | CQ1: 10100 | CR1: 10101 | CS1: 10102 | CT1: 10103 | CU1: 10105 | CV1: 10106 | CW1: 10107 | CX1: 10108 | CY1: 10110 | CZ1: 10111 | DA1: 10112 | DB1: 10113 | DC1: 10114 | DD1: 10115 | DE1: 10116 | DF1: 10117 | DG1: 10118 | DH1: 10119 | DI1: 10120 | DJ1: 10121 | DK1: 10122 | DL1: 10123 | DM1: 10124 | DN1: 10125 | DO1: 10126 | DP1: 10127 | DQ1: 10128 | DR1: 10129 | DS1: 10130 | DT1: 10131 | DU1: 10132 | DV1: 10133 | DW1: 10135 | DX1: 10136 | DY1: 10138 | DZ1: 10139 | EA1: 10140 | EB1: 10141 | EC1: 10142 | ED1: 10143 | EE1: 10144 | EF1: 10145 | EG1: 10146 | EH1: 10147 | EI1: 10148 | EJ1: 10149 | EK1: 10150 | EL1: 10151 | EM1: 10152 | EN1: 10154 | EO1: 10155 | EP1: 10156 | EQ1: 10157 | ER1: 10158 | ES1: 10159 | ET1: 10160 | EU1: 10161 | EV1: 10162 | EW1: 10163 | EX1: 10164 | EY1: 10165 | EZ1: 10166 | FA1: 10167 | FB1: 10168 | FC1: 10170 | FD1: 10171 | FE1: 10172 | FF1: 10173 | FG1: 10174 | FH1: 10175 | FI1: 10178 | FJ1: 10179 | FK1: 10180 | FL1: 10181 | FM1: 10183 | FN1: 10184 | FO1: 10185 | FP1: 10186 | FQ1: 10187 | FR1: 10188 | FS1: 10190 | FT1: 10191 | FU1: 10192 | FV1: 10193 | FW1: 10194 | FX1: 10195 | FY1: 10196 | FZ1: 10197 | GA1: 10198 | GB1: 10199 | GC1: 10200 | GD1: 10201 | GE1: 10202 | GF1: 10207 | GG1: 10208 | GH1: 10209 | GI1: 10210 | GJ1: 10211 | GK1: 10212 | GL1: 10214 | GM1: 10215 | GN1: 10216 | GO1: 10217 | GP1: 10218 | GQ1: 10220 | GR1: 10222 | GS1: 10223 | GT1: 10226 | GU1: 10229 | GV1: 10232 | GW1: 10233 | GX1: 10234 | GY1: 10235 | GZ1: 10238 | HA1: 10239 | HB1: 10240 | HC1: 10241 | HD1: 10243 | HE1: 10244 | HF1: 10245 | HG1: 10246 | HH1: 10247 | HI1: 10248 | HJ1: 10249 | HK1: 10251 | HL1: 10252 | HM1: 10253 | HN1: 10254 | HO1: 10257 | HP1: 10260 | HQ1: 10261 | HR1: 10262 | HS1: 10263 | HT1: 10264 | HU1: 10266 | HV1: 10267 | HW1: 10268 | HX1: 10269 | HY1: 10270 | HZ1: 10271 | IA1: 10273 | IB1: 10274 | IC1: 10275 | ID1: 10277 | IE1: 10280 | IF1: 10281 | IG1: 10286 | IH1: 10287 | II1: 10289 | IJ1: 10290 | IK1: 10291 | IL1: 10294 | IM1: 10295 | IN1: 10296 | IO1: 10302 | IP1: 10303 | IQ1: 10304 | IR1: 10305 | IS1: 10306 | IT1: 10307 | IU1: 10308 | IV1: 10309 | IW1: 10311 | IX1: 10312 | IY1: 10313 | IZ1: 10314 | JA1: 10315 | JB1: 10316 | JC1: 10317 | JD1: 10318 | JE1: 10320 | JF1: 10321 | JG1: 10322 | JH1: 10324 | JI1: 10325 | JJ1: 10326 | JK1: 10327 | JL1: 10328 | JM1: 10329 | JN1: 10330 | JO1: 10332 | JP1: 10336 | JQ1: 10338 | JR1: 10339 | JS1: 10341 | JT1: 10342 | JU1: 10343 | JV1: 10344 | JW1: 10345 | JX1: 10347 | JY1: 10350 | JZ1: 10351 | KA1: 10352 | KB1: 10355 | KC1: 10356 | KD1: 10357 | KE1: 10358 | KF1: 10359 | KG1: 10360 | KH1: 10361 | KI1: 10365 | KJ1: 10366 | KK1: 10367 | KL1: 10369 | KM1: 10370 | KN1: 10371 | KO1: 10372 | KP1: 10373 | KQ1: 10374 | KR1: 10376 | KS1: 10379 | KT1: 10381 | KU1: 10383 | KV1: 10384 | KW1: 10385 | KX1: 10386 | KY1: 10387 | KZ1: 10388 | LA1: 10390 | LB1: 10392 | LC1: 10393 | LD1: 10394 | LE1: 10395 | LF1: 10396 | LG1: 10398 | LH1: 10399 | LI1: 10403 | LJ1: 10405 | LK1: 10406 | LL1: 10407 | LM1: 10409 | LN1: 10411 | LO1: 10413 | LP1: 10414 | LQ1: 10417 | LR1: 10418 | LS1: 10422 | LT1: 10423 | LU1: 10427 | LV1: 10431 | LW1: 10434 | LX1: 10435 | LY1: 10436 | LZ1: 10438 | MA1: 10439 | MB1: 10440 | MC1: 10441 | MD1: 10442 | ME1: 10444 | MF1: 10447 | MG1: 10448 | MH1: 10452 | MI1: 10454 | MJ1: 10455 | MK1: 10457 | ML1: 10460 | MM1: 10463 | MN1: 10464 | MO1: 10465 | MP1: 10466 | MQ1: 10468 | MR1: 10470 | MS1: 10472 | MT1: 10480 | MU1: 10481 | MV1: 10482 | MW1: 10485 | MX1: 10486 | MY1: 10487 | MZ1: 10489 | NA1: 10490 | NB1: 10491 | NC1: 10493 | ND1: 10494 | NE1: 10495 | NF1: 10496 | NG1: 10497 | NH1: 10498 | NI1: 10500
A2: Customer ID | B2: 1102 | C2: 1435 | D2: 1860 | E2: 1270 | F2: 1106 | G2: 1071 | H2: 1700 | I2: 1020 | J2: 1614 | K2: 1121 | L2: 1466 | M2: 1214 | N2: 1330 | O2: 1458 | P2: 1087 | Q2: 1372 | R2: 1099 | S2: 1871 | T2: 1663 | U2: 1130 | V2: 1661 | W2: 1308 | X2: 1769 | Y2: 1343 | Z2: 1491 | AA2: 1413 | AB2: 1805 | AC2: 1385 | AD2: 1191 | AE2: 1955 | AF2: 1276 | AG2: 1160 | AH2: 1459 | AI2: 1313 | AJ2: 1021 | AK2: 1252 | AL2: 1747 | AM2: 1856 | AN2: 1560 | AO2: 1474 | AP2: 1058 | AQ2: 1510 | AR2: 1681 | AS2: 1475 | AT2: 1699 | AU2: 1975 | AV2: 1782 | AW2: 1189 | AX2: 1957 | AY2: 1686 | AZ2: 1562 | BA2: 1875 | BB2: 1566 | BC2: 1243 | BD2: 1831 | BE2: 1504 | BF2: 1484 | BG2: 1818 | BH2: 1646 | BI2: 1840 | BJ2: 1166 | BK2: 1273 | BL2: 1387 | BM2: 1600 | BN2: 1315 | BO2: 1013 | BP2: 1241 | BQ2: 1776 | BR2: 1345 | BS2: 1564 | BT2: 1897 | BU2: 1339 | BV2: 1091 | BW2: 1366 | BX2: 1454 | BY2: 1427 | BZ2: 1508 | CA2: 1775 | CB2: 1942 | CC2: 1034 | CD2: 1205 | CE2: 1080 | CF2: 1931 | CG2: 1561 | CH2: 1001 | CI2: 1389 | CJ2: 1565 | CK2: 1105 | CL2: 1771 | CM2: 1821 | CN2: 1476 | CO2: 1702 | CP2: 1401 | CQ2: 1729 | CR2: 1555 | CS2: 1161 | CT2: 1201 | CU2: 1995 | CV2: 1269 | CW2: 1862 | CX2: 1815 | CY2: 1455 | CZ2: 1461 | DA2: 1726 | DB2: 1251 | DC2: 1701 | DD2: 1295 | DE2: 1724 | DF2: 1719 | DG2: 1748 | DH2: 1337 | DI2: 1878 | DJ2: 1052 | DK2: 1791 | DL2: 1921 | DM2: 1216 | DN2: 1763 | DO2: 1187 | DP2: 1379 | DQ2: 1492 | DR2: 1040 | DS2: 1156 | DT2: 1014 | DU2: 1812 | DV2: 1064 | DW2: 1838 | DX2: 1520 | DY2: 1128 | DZ2: 1647 | EA2: 1471 | EB2: 1062 | EC2: 1138 | ED2: 1498 | EE2: 1592 | EF2: 1391 | EG2: 1674 | EH2: 1418 | EI2: 1288 | EJ2: 1378 | EK2: 1772 | EL2: 1489 | EM2: 1230 | EN2: 1027 | EO2: 1134 | EP2: 1200 | EQ2: 1839 | ER2: 1779 | ES2: 1929 | ET2: 1032 | EU2: 1047 | EV2: 1502 | EW2: 1406 | EX2: 1573 | EY2: 1727 | EZ2: 1804 | FA2: 1098 | FB2: 1683 | FC2: 1725 | FD2: 1986 | FE2: 1546 | FF2: 1960 | FG2: 1738 | FH2: 1612 | FI2: 1642 | FJ2: 1768 | FK2: 1004 | FL2: 1217 | FM2: 1766 | FN2: 1397 | FO2: 1870 | FP2: 1794 | FQ2: 1392 | FR2: 1206 | FS2: 1857 | FT2: 1553 | FU2: 1891 | FV2: 1460 | FW2: 1690 | FX2: 1574 | FY2: 1863 | FZ2: 1742 | GA2: 1240 | GB2: 1563 | GC2: 1095 | GD2: 1899 | GE2: 1733 | GF2: 1654 | GG2: 1170 | GH2: 1540 | GI2: 1035 | GJ2: 1524 | GK2: 1159 | GL2: 1698 | GM2: 1242 | GN2: 1085 | GO2: 1795 | GP2: 1577 | GQ2: 1556 | GR2: 1952 | GS2: 1645 | GT2: 1619 | GU2: 1797 | GV2: 1639 | GW2: 1505 | GX2: 1347 | GY2: 1472 | GZ2: 1224 | HA2: 1384 | HB2: 1376 | HC2: 1282 | HD2: 1632 | HE2: 1627 | HF2: 1972 | HG2: 1744 | HH2: 1258 | HI2: 1358 | HJ2: 1709 | HK2: 1410 | HL2: 1648 | HM2: 1317 | HN2: 1676 | HO2: 1233 | HP2: 1974 | HQ2: 1826 | HR2: 1373 | HS2: 1671 | HT2: 1607 | HU2: 1232 | HV2: 1691 | HW2: 1112 | HX2: 1829 | HY2: 1496 | HZ2: 1441 | IA2: 1267 | IB2: 1509 | IC2: 1806 | ID2: 1386 | IE2: 1624 | IF2: 1951 | IG2: 1641 | IH2: 1219 | II2: 1854 | IJ2: 1996 | IK2: 1735 | IL2: 1402 | IM2: 1637 | IN2: 1129 | IO2: 1415 | IP2: 1246 | IQ2: 1835 | IR2: 1438 | IS2: 1202 | IT2: 1183 | IU2: 1122 | IV2: 1400 | IW2: 1293 | IX2: 1279 | IY2: 1836 | IZ2: 1883 | JA2: 1609 | JB2: 1197 | JC2: 1981 | JD2: 1906 | JE2: 1751 | JF2: 1143 | JG2: 1608 | JH2: 1123 | JI2: 1186 | JJ2: 1325 | JK2: 1463 | JL2: 1348 | JM2: 1770 | JN2: 1659 | JO2: 1954 | JP2: 1962 | JQ2: 1146 | JR2: 1147 | JS2: 1710 | JT2: 1819 | JU2: 1488 | JV2: 1928 | JW2: 1935 | JX2: 1550 | JY2: 1640 | JZ2: 1778 | KA2: 1987 | KB2: 1945 | KC2: 1150 | KD2: 1414 | KE2: 1989 | KF2: 1297 | KG2: 1610 | KH2: 1262 | KI2: 1623 | KJ2: 1571 | KK2: 1880 | KL2: 1896 | KM2: 1303 | KN2: 1253 | KO2: 1651 | KP2: 1452 | KQ2: 1036 | KR2: 1008 | KS2: 1658 | KT2: 1207 | KU2: 1403 | KV2: 1151 | KW2: 1053 | KX2: 1119 | KY2: 1672 | KZ2: 1919 | LA2: 1586 | LB2: 1967 | LC2: 1419 | LD2: 1421 | LE2: 1103 | LF2: 1851 | LG2: 1226 | LH2: 1111 | LI2: 1152 | LJ2: 1913 | LK2: 1895 | LL2: 1877 | LM2: 1705 | LN2: 1162 | LO2: 1956 | LP2: 1680 | LQ2: 1579 | LR2: 1800 | LS2: 1915 | LT2: 1503 | LU2: 1194 | LV2: 1687 | LW2: 1882 | LX2: 1469 | LY2: 1374 | LZ2: 1749 | MA2: 1669 | MB2: 1037 | MC2: 1229 | MD2: 1364 | ME2: 1437 | MF2: 1026 | MG2: 1225 | MH2: 1283 | MI2: 1959 | MJ2: 1480 | MK2: 1828 | ML2: 1515 | MM2: 1048 | MN2: 1511 | MO2: 1016 | MP2: 1171 | MQ2: 1157 | MR2: 1045 | MS2: 1517 | MT2: 1301 | MU2: 1180 | MV2: 1606 | MW2: 1992 | MX2: 1115 | MY2: 1190 | MZ2: 1980 | NA2: 1927 | NB2: 1982 | NC2: 1255 | ND2: 1322 | NE2: 1127 | NF2: 1017 | NG2: 1792 | NH2: 1734 | NI2: 1569
